Workbook
Name ORDATA: [1]ORDATA!$B$3:$AV$2500
Name ORINDEX: [1]ORDATA!$B$2:$AS$2

Sheet check dali wipday
N1: 7-10 | P1: คำนวนถึงวันที่
N2: 0-6 | P2: 46265
A3: Material | B3: Matl group | C3: Component | D3: order | E3: Max Order-FO | F3: Next month 30% | G3: total fo+30% | H3: order avg/day | I3: fg | J3: wip | K3: total | L3: 20 | M3: note | N3: กรอง wip day | O3: Order | P3: กรอง diff ord | Q3: วันที่ขาด
A4: 19923 | B4: F-RP | C4: 19923;A | D4: =SUMIF(fo!C:C,A4,fo!U:U) -> 0 | E4: =SUMIF(fo!C:C,A4,fo!T:T) -> 0 | F4: =SUMIF(fo!C:C,A4,fo!Z:Z) -> 0 | G4: =SUM(E4:F4) -> 0 | H4: =G4/$L$3 -> 0 | I4: =SUMIF('dali wip-fg'!A:A,A4,'dali wip-fg'!F:F) -> 0 | J4: =SUMIF('dali wip-fg'!A:A,C4,'dali wip-fg'!F:F) -> 0 | K4: =+I4+J4 -> 0 | L4: =+K4/H4 -> #DIV/0! | N4: =IF(L4<6,"แดง",IF(AND(L4>=7,L4<=10),"เหลือง","อื่นๆ")) -> #DIV/0! | O4: =SUMIFS(ord!$F:$F, ord!$C:$C,'check dali wipday'!A4, ord!$G:$G, ">="&DATE(2025,1,1), ord!$G:$G, "<="&$P$2) -> 0 | P4: =+K4-O4 -> 0 | Q4: =IF(_xlfn.MINIFS('ord check'!C:C,'ord check'!$A:$A,'check dali wipday'!A4,'ord check'!J:J,"<0")=0,"",_xlfn.MINIFS('ord check'!C:C,'ord check'!A:A,'check dali wipday'!A4,'ord check'!J:J,"<0"))
A5: 1182003 | B5: F-RPM | C5: 1182003;A | D5: =SUMIF(fo!C:C,A5,fo!U:U) -> 0 | E5: =SUMIF(fo!C:C,A5,fo!T:T) -> 0 | F5: =SUMIF(fo!C:C,A5,fo!Z:Z) -> 0 | G5: =SUM(E5:F5) -> 0 | H5: =G5/$L$3 -> 0 | I5: =SUMIF('dali wip-fg'!A:A,A5,'dali wip-fg'!F:F) -> 0 | J5: =SUMIF('dali wip-fg'!A:A,C5,'dali wip-fg'!F:F) -> 0 | K5: =+I5+J5 -> 0 | L5: =+K5/H5 -> #DIV/0! | N5: =IF(L5<6,"แดง",IF(AND(L5>=7,L5<=10),"เหลือง","อื่นๆ")) -> #DIV/0! | O5: =SUMIFS(ord!$F:$F, ord!$C:$C,'check dali wipday'!A5, ord!$G:$G, ">="&DATE(2025,1,1), ord!$G:$G, "<="&$P$2) -> 0 | P5: =+K5-O5 -> 0 | Q5: =IF(_xlfn.MINIFS('ord check'!C:C,'ord check'!$A:$A,'check dali wipday'!A5,'ord check'!J:J,"<0")=0,"",_xlfn.MINIFS('ord check'!C:C,'ord check'!A:A,'check dali wipday'!A5,'ord check'!J:J,"<0"))
A6: 1182011 | B6: F-EM | C6: 1182011;A | D6: =SUMIF(fo!C:C,A6,fo!U:U) -> 0 | E6: =SUMIF(fo!C:C,A6,fo!T:T) -> 0 | F6: =SUMIF(fo!C:C,A6,fo!Z:Z) -> 0 | G6: =SUM(E6:F6) -> 0 | H6: =G6/$L$3 -> 0 | I6: =SUMIF('dali wip-fg'!A:A,A6,'dali wip-fg'!F:F) -> 0 | J6: =SUMIF('dali wip-fg'!A:A,C6,'dali wip-fg'!F:F) -> 0 | K6: =+I6+J6 -> 0 | L6: =+K6/H6 -> #DIV/0! | N6: =IF(L6<6,"แดง",IF(AND(L6>=7,L6<=10),"เหลือง","อื่นๆ")) -> #DIV/0! | O6: =SUMIFS(ord!$F:$F, ord!$C:$C,'check dali wipday'!A6, ord!$G:$G, ">="&DATE(2025,1,1), ord!$G:$G, "<="&$P$2) -> 0 | P6: =+K6-O6 -> 0 | Q6: =IF(_xlfn.MINIFS('ord check'!C:C,'ord check'!$A:$A,'check dali wipday'!A6,'ord check'!J:J,"<0")=0,"",_xlfn.MINIFS('ord check'!C:C,'ord check'!A:A,'check dali wipday'!A6,'ord check'!J:J,"<0"))
A7: 1184469 | B7: F-RPM | C7: 1184469;A | D7: =SUMIF(fo!C:C,A7,fo!U:U) -> 0 | E7: =SUMIF(fo!C:C,A7,fo!T:T) -> 0 | F7: =SUMIF(fo!C:C,A7,fo!Z:Z) -> 0 | G7: =SUM(E7:F7) -> 0 | H7: =G7/$L$3 -> 0 | I7: =SUMIF('dali wip-fg'!A:A,A7,'dali wip-fg'!F:F) -> 0 | J7: =SUMIF('dali wip-fg'!A:A,C7,'dali wip-fg'!F:F) -> 0 | K7: =+I7+J7 -> 0 | L7: =+K7/H7 -> #DIV/0! | N7: =IF(L7<6,"แดง",IF(AND(L7>=7,L7<=10),"เหลือง","อื่นๆ")) -> #DIV/0! | O7: =SUMIFS(ord!$F:$F, ord!$C:$C,'check dali wipday'!A7, ord!$G:$G, ">="&DATE(2025,1,1), ord!$G:$G, "<="&$P$2) -> 0 | P7: =+K7-O7 -> 0 | Q7: =IF(_xlfn.MINIFS('ord check'!C:C,'ord check'!$A:$A,'check dali wipday'!A7,'ord check'!J:J,"<0")=0,"",_xlfn.MINIFS('ord check'!C:C,'ord check'!A:A,'check dali wipday'!A7,'ord check'!J:J,"<0"))
A8: 1189300 | B8: F-RPM | C8: 1189300;A | D8: =SUMIF(fo!C:C,A8,fo!U:U) -> 0 | E8: =SUMIF(fo!C:C,A8,fo!T:T) -> 0 | F8: =SUMIF(fo!C:C,A8,fo!Z:Z) -> 0 | G8: =SUM(E8:F8) -> 0 | H8: =G8/$L$3 -> 0 | I8: =SUMIF('dali wip-fg'!A:A,A8,'dali wip-fg'!F:F) -> 0 | J8: =SUMIF('dali wip-fg'!A:A,C8,'dali wip-fg'!F:F) -> 0 | K8: =+I8+J8 -> 0 | L8: =+K8/H8 -> #DIV/0! | N8: =IF(L8<6,"แดง",IF(AND(L8>=7,L8<=10),"เหลือง","อื่นๆ")) -> #DIV/0! | O8: =SUMIFS(ord!$F:$F, ord!$C:$C,'check dali wipday'!A8, ord!$G:$G, ">="&DATE(2025,1,1), ord!$G:$G, "<="&$P$2) -> 0 | P8: =+K8-O8 -> 0 | Q8: =IF(_xlfn.MINIFS('ord check'!C:C,'ord check'!$A:$A,'check dali wipday'!A8,'ord check'!J:J,"<0")=0,"",_xlfn.MINIFS('ord check'!C:C,'ord check'!A:A,'check dali wipday'!A8,'ord check'!J:J,"<0"))
A9: 1189988 | B9: F-RPM | C9: 1189988;A | D9: =SUMIF(fo!C:C,A9,fo!U:U) -> 0 | E9: =SUMIF(fo!C:C,A9,fo!T:T) -> 0 | F9: =SUMIF(fo!C:C,A9,fo!Z:Z) -> 0 | G9: =SUM(E9:F9) -> 0 | H9: =G9/$L$3 -> 0 | I9: =SUMIF('dali wip-fg'!A:A,A9,'dali wip-fg'!F:F) -> 0 | J9: =SUMIF('dali wip-fg'!A:A,C9,'dali wip-fg'!F:F) -> 0 | K9: =+I9+J9 -> 0 | L9: =+K9/H9 -> #DIV/0! | N9: =IF(L9<6,"แดง",IF(AND(L9>=7,L9<=10),"เหลือง","อื่นๆ")) -> #DIV/0! | O9: =SUMIFS(ord!$F:$F, ord!$C:$C,'check dali wipday'!A9, ord!$G:$G, ">="&DATE(2025,1,1), ord!$G:$G, "<="&$P$2) -> 0 | P9: =+K9-O9 -> 0 | Q9: =IF(_xlfn.MINIFS('ord check'!C:C,'ord check'!$A:$A,'check dali wipday'!A9,'ord check'!J:J,"<0")=0,"",_xlfn.MINIFS('ord check'!C:C,'ord check'!A:A,'check dali wipday'!A9,'ord check'!J:J,"<0"))
A10: 5848516 | B10: F-RP | C10: 5848516;A | D10: =SUMIF(fo!C:C,A10,fo!U:U) -> 0 | E10: =SUMIF(fo!C:C,A10,fo!T:T) -> 0 | F10: =SUMIF(fo!C:C,A10,fo!Z:Z) -> 0 | G10: =SUM(E10:F10) -> 0 | H10: =G10/$L$3 -> 0 | I10: =SUMIF('dali wip-fg'!A:A,A10,'dali wip-fg'!F:F) -> 0 | J10: =SUMIF('dali wip-fg'!A:A,C10,'dali wip-fg'!F:F) -> 0 | K10: =+I10+J10 -> 0 | L10: =+K10/H10 -> #DIV/0! | N10: =IF(L10<6,"แดง",IF(AND(L10>=7,L10<=10),"เหลือง","อื่นๆ")) -> #DIV/0! | O10: =SUMIFS(ord!$F:$F, ord!$C:$C,'check dali wipday'!A10, ord!$G:$G, ">="&DATE(2025,1,1), ord!$G:$G, "<="&$P$2) -> 0 | P10: =+K10-O10 -> 0 | Q10: =IF(_xlfn.MINIFS('ord check'!C:C,'ord check'!$A:$A,'check dali wipday'!A10,'ord check'!J:J,"<0")=0,"",_xlfn.MINIFS('ord check'!C:C,'ord check'!A:A,'check dali wipday'!A10,'ord check'!J:J,"<0"))
A11: 97215052 | B11: F-EM | C11: 97215052;A | D11: =SUMIF(fo!C:C,A11,fo!U:U) -> 0 | E11: =SUMIF(fo!C:C,A11,fo!T:T) -> 0 | F11: =SUMIF(fo!C:C,A11,fo!Z:Z) -> 0 | G11: =SUM(E11:F11) -> 0 | H11: =G11/$L$3 -> 0 | I11: =SUMIF('dali wip-fg'!A:A,A11,'dali wip-fg'!F:F) -> 0 | J11: =SUMIF('dali wip-fg'!A:A,C11,'dali wip-fg'!F:F) -> 0 | K11: =+I11+J11 -> 0 | L11: =+K11/H11 -> #DIV/0! | N11: =IF(L11<6,"แดง",IF(AND(L11>=7,L11<=10),"เหลือง","อื่นๆ")) -> #DIV/0! | O11: =SUMIFS(ord!$F:$F, ord!$C:$C,'check dali wipday'!A11, ord!$G:$G, ">="&DATE(2025,1,1), ord!$G:$G, "<="&$P$2) -> 0 | P11: =+K11-O11 -> 0 | Q11: =IF(_xlfn.MINIFS('ord check'!C:C,'ord check'!$A:$A,'check dali wipday'!A11,'ord check'!J:J,"<0")=0,"",_xlfn.MINIFS('ord check'!C:C,'ord check'!A:A,'check dali wipday'!A11,'ord check'!J:J,"<0"))
A12: 97235925 | B12: F-EM | C12: 97235925;A | D12: =SUMIF(fo!C:C,A12,fo!U:U) -> 0 | E12: =SUMIF(fo!C:C,A12,fo!T:T) -> 0 | F12: =SUMIF(fo!C:C,A12,fo!Z:Z) -> 0 | G12: =SUM(E12:F12) -> 0 | H12: =G12/$L$3 -> 0 | I12: =SUMIF('dali wip-fg'!A:A,A12,'dali wip-fg'!F:F) -> 1868 | J12: =SUMIF('dali wip-fg'!A:A,C12,'dali wip-fg'!F:F) -> 0 | K12: =+I12+J12 -> 1868 | L12: =+K12/H12 -> #DIV/0! | N12: =IF(L12<6,"แดง",IF(AND(L12>=7,L12<=10),"เหลือง","อื่นๆ")) -> #DIV/0! | O12: =SUMIFS(ord!$F:$F, ord!$C:$C,'check dali wipday'!A12, ord!$G:$G, ">="&DATE(2025,1,1), ord!$G:$G, "<="&$P$2) -> 0 | P12: =+K12-O12 -> 1868 | Q12: =IF(_xlfn.MINIFS('ord check'!C:C,'ord check'!$A:$A,'check dali wipday'!A12,'ord check'!J:J,"<0")=0,"",_xlfn.MINIFS('ord check'!C:C,'ord check'!A:A,'check dali wipday'!A12,'ord check'!J:J,"<0"))
A13: 97946549 | B13: F-EM | C13: 97946549;A | D13: =SUMIF(fo!C:C,A13,fo!U:U) -> 0 | E13: =SUMIF(fo!C:C,A13,fo!T:T) -> 0 | F13: =SUMIF(fo!C:C,A13,fo!Z:Z) -> 0 | G13: =SUM(E13:F13) -> 0 | H13: =G13/$L$3 -> 0 | I13: =SUMIF('dali wip-fg'!A:A,A13,'dali wip-fg'!F:F) -> 51 | J13: =SUMIF('dali wip-fg'!A:A,C13,'dali wip-fg'!F:F) -> 0 | K13: =+I13+J13 -> 51 | L13: =+K13/H13 -> #DIV/0! | N13: =IF(L13<6,"แดง",IF(AND(L13>=7,L13<=10),"เหลือง","อื่นๆ")) -> #DIV/0! | O13: =SUMIFS(ord!$F:$F, ord!$C:$C,'check dali wipday'!A13, ord!$G:$G, ">="&DATE(2025,1,1), ord!$G:$G, "<="&$P$2) -> 0 | P13: =+K13-O13 -> 51 | Q13: =IF(_xlfn.MINIFS('ord check'!C:C,'ord check'!$A:$A,'check dali wipday'!A13,'ord check'!J:J,"<0")=0,"",_xlfn.MINIFS('ord check'!C:C,'ord check'!A:A,'check dali wipday'!A13,'ord check'!J:J,"<0"))
A14: 97946803 | B14: F-EM | C14: 97946803;A | D14: =SUMIF(fo!C:C,A14,fo!U:U) -> 0 | E14: =SUMIF(fo!C:C,A14,fo!T:T) -> 0 | F14: =SUMIF(fo!C:C,A14,fo!Z:Z) -> 0 | G14: =SUM(E14:F14) -> 0 | H14: =G14/$L$3 -> 0 | I14: =SUMIF('dali wip-fg'!A:A,A14,'dali wip-fg'!F:F) -> 0 | J14: =SUMIF('dali wip-fg'!A:A,C14,'dali wip-fg'!F:F) -> 0 | K14: =+I14+J14 -> 0 | L14: =+K14/H14 -> #DIV/0! | N14: =IF(L14<6,"แดง",IF(AND(L14>=7,L14<=10),"เหลือง","อื่นๆ")) -> #DIV/0! | O14: =SUMIFS(ord!$F:$F, ord!$C:$C,'check dali wipday'!A14, ord!$G:$G, ">="&DATE(2025,1,1), ord!$G:$G, "<="&$P$2) -> 0 | P14: =+K14-O14 -> 0 | Q14: =IF(_xlfn.MINIFS('ord check'!C:C,'ord check'!$A:$A,'check dali wipday'!A14,'ord check'!J:J,"<0")=0,"",_xlfn.MINIFS('ord check'!C:C,'ord check'!A:A,'check dali wipday'!A14,'ord check'!J:J,"<0"))
A15: 98181937 | B15: F-RP | C15: 98181937;A | D15: =SUMIF(fo!C:C,A15,fo!U:U) -> 0 | E15: =SUMIF(fo!C:C,A15,fo!T:T) -> 0 | F15: =SUMIF(fo!C:C,A15,fo!Z:Z) -> 0 | G15: =SUM(E15:F15) -> 0 | H15: =G15/$L$3 -> 0 | I15: =SUMIF('dali wip-fg'!A:A,A15,'dali wip-fg'!F:F) -> 0 | J15: =SUMIF('dali wip-fg'!A:A,C15,'dali wip-fg'!F:F) -> 0 | K15: =+I15+J15 -> 0 | L15: =+K15/H15 -> #DIV/0! | N15: =IF(L15<6,"แดง",IF(AND(L15>=7,L15<=10),"เหลือง","อื่นๆ")) -> #DIV/0! | O15: =SUMIFS(ord!$F:$F, ord!$C:$C,'check dali wipday'!A15, ord!$G:$G, ">="&DATE(2025,1,1), ord!$G:$G, "<="&$P$2) -> 0 | P15: =+K15-O15 -> 0 | Q15: =IF(_xlfn.MINIFS('ord check'!C:C,'ord check'!$A:$A,'check dali wipday'!A15,'ord check'!J:J,"<0")=0,"",_xlfn.MINIFS('ord check'!C:C,'ord check'!A:A,'check dali wipday'!A15,'ord check'!J:J,"<0"))
... A29: 8975385310 | B29: F-RP | C29: 8975385310;A | D29: =SUMIF(fo!C:C,A29,fo!U:U) -> 0 | E29: =SUMIF(fo!C:C,A29,fo!T:T) -> 0 | F29: =SUMIF(fo!C:C,A29,fo!Z:Z) -> 0 | G29: =SUM(E29:F29) -> 0 | H29: =G29/$L$3 -> 0 | I29: =SUMIF('dali wip-fg'!A:A,A29,'dali wip-fg'!F:F) -> 0 | J29: =SUMIF('dali wip-fg'!A:A,C29,'dali wip-fg'!F:F) -> 0 | K29: =+I29+J29 -> 0 | L29: =+K29/H29 -> #DIV/0! | N29: =IF(L29<6,"แดง",IF(AND(L29>=7,L29<=10),"เหลือง","อื่นๆ")) -> #DIV/0! | O29: =SUMIFS(ord!$F:$F, ord!$C:$C,'check dali wipday'!A29, ord!$G:$G, ">="&DATE(2025,1,1), ord!$G:$G, "<="&$P$2) -> 0 | P29: =+K29-O29 -> 0 | Q29: =IF(_xlfn.MINIFS('ord check'!C:C,'ord check'!$A:$A,'check dali wipday'!A29,'ord check'!J:J,"<0")=0,"",_xlfn.MINIFS('ord check'!C:C,'ord check'!A:A,'check dali wipday'!A29,'ord check'!J:J,"<0"))
A30: 8975579810 | B30: F-RPM | C30: 8975579810;A | D30: =SUMIF(fo!C:C,A30,fo!U:U) -> 48 | E30: =SUMIF(fo!C:C,A30,fo!T:T) -> 96 | F30: =SUMIF(fo!C:C,A30,fo!Z:Z) -> 22 | G30: =SUM(E30:F30) -> 118 | H30: =G30/$L$3 -> 5.9 | I30: =SUMIF('dali wip-fg'!A:A,A30,'dali wip-fg'!F:F) -> 36 | J30: =SUMIF('dali wip-fg'!A:A,C30,'dali wip-fg'!F:F)/2 -> 363 | K30: =+I30+J30 -> 399 | L30: =+K30/H30 -> 67.627119 | M30: งานเรียกน้อยต้องอบก่อน | N30: =IF(L30<6,"แดง",IF(AND(L30>=7,L30<=10),"เหลือง","อื่นๆ")) -> อื่นๆ | O30: =SUMIFS(ord!$F:$F, ord!$C:$C,'check dali wipday'!A30, ord!$G:$G, ">="&DATE(2025,1,1), ord!$G:$G, "<="&$P$2) -> 48 | P30: =+K30-O30 -> 351 | Q30: =IF(_xlfn.MINIFS('ord check'!C:C,'ord check'!$A:$A,'check dali wipday'!A30,'ord check'!J:J,"<0")=0,"",_xlfn.MINIFS('ord check'!C:C,'ord check'!A:A,'check dali wipday'!A30,'ord check'!J:J,"<0"))
A31: 8978291420 | B31: F-RP | C31: 8978291420;A | D31: =SUMIF(fo!C:C,A31,fo!U:U) -> 0 | E31: =SUMIF(fo!C:C,A31,fo!T:T) -> 0 | F31: =SUMIF(fo!C:C,A31,fo!Z:Z) -> 0 | G31: =SUM(E31:F31) -> 0 | H31: =G31/$L$3 -> 0 | I31: =SUMIF('dali wip-fg'!A:A,A31,'dali wip-fg'!F:F) -> 0 | J31: =SUMIF('dali wip-fg'!A:A,C31,'dali wip-fg'!F:F) -> 0 | K31: =+I31+J31 -> 0 | L31: =+K31/H31 -> #DIV/0! | N31: =IF(L31<6,"แดง",IF(AND(L31>=7,L31<=10),"เหลือง","อื่นๆ")) -> #DIV/0! | O31: =SUMIFS(ord!$F:$F, ord!$C:$C,'check dali wipday'!A31, ord!$G:$G, ">="&DATE(2025,1,1), ord!$G:$G, "<="&$P$2) -> 0 | P31: =+K31-O31 -> 0 | Q31: =IF(_xlfn.MINIFS('ord check'!C:C,'ord check'!$A:$A,'check dali wipday'!A31,'ord check'!J:J,"<0")=0,"",_xlfn.MINIFS('ord check'!C:C,'ord check'!A:A,'check dali wipday'!A31,'ord check'!J:J,"<0"))
A32: 8983517840 | B32: F-RP | C32: 8983517840;A | D32: =SUMIF(fo!C:C,A32,fo!U:U) -> 0 | E32: =SUMIF(fo!C:C,A32,fo!T:T) -> 0 | F32: =SUMIF(fo!C:C,A32,fo!Z:Z) -> 0 | G32: =SUM(E32:F32) -> 0 | H32: =G32/$L$3 -> 0 | I32: =SUMIF('dali wip-fg'!A:A,A32,'dali wip-fg'!F:F) -> 0 | J32: =SUMIF('dali wip-fg'!A:A,C32,'dali wip-fg'!F:F) -> 15 | K32: =+I32+J32 -> 15 | L32: =+K32/H32 -> #DIV/0! | N32: =IF(L32<6,"แดง",IF(AND(L32>=7,L32<=10),"เหลือง","อื่นๆ")) -> #DIV/0! | O32: =SUMIFS(ord!$F:$F, ord!$C:$C,'check dali wipday'!A32, ord!$G:$G, ">="&DATE(2025,1,1), ord!$G:$G, "<="&$P$2) -> 0 | P32: =+K32-O32 -> 15 | Q32: =IF(_xlfn.MINIFS('ord check'!C:C,'ord check'!$A:$A,'check dali wipday'!A32,'ord check'!J:J,"<0")=0,"",_xlfn.MINIFS('ord check'!C:C,'ord check'!A:A,'check dali wipday'!A32,'ord check'!J:J,"<0"))
A33: 8983943812 | B33: F-RP | C33: 8983943810;A | D33: =SUMIF(fo!C:C,A33,fo!U:U) -> 1265 | E33: =SUMIF(fo!C:C,A33,fo!T:T) -> 3411 | F33: =SUMIF(fo!C:C,A33,fo!Z:Z) -> 873 | G33: =SUM(E33:F33) -> 4284 | H33: =G33/$L$3 -> 214.2 | I33: =SUMIF('dali wip-fg'!A:A,A33,'dali wip-fg'!F:F) -> 194 | J33: =SUMIF('dali wip-fg'!A:A,C33,'dali wip-fg'!F:F) -> 1478 | K33: =+I33+J33 -> 1672 | L33: =+K33/H33 -> 7.805789 | M33: ให้ดู WIP DAY | N33: =IF(L33<6,"แดง",IF(AND(L33>=7,L33<=10),"เหลือง","อื่นๆ")) -> เหลือง | O33: =SUMIFS(ord!$F:$F, ord!$C:$C,'check dali wipday'!A33, ord!$G:$G, ">="&DATE(2025,1,1), ord!$G:$G, "<="&$P$2) -> 1347 | P33: =+K33-O33 -> 325 | Q33: ให้ดู WIP DAY
A34: 8983943831 | B34: F-RP | C34: 8983943830;A | D34: =SUMIF(fo!C:C,A34,fo!U:U) -> 3 | E34: =SUMIF(fo!C:C,A34,fo!T:T) -> 115 | F34: =SUMIF(fo!C:C,A34,fo!Z:Z) -> 51 | G34: =SUM(E34:F34) -> 166 | H34: =G34/$L$3 -> 8.3 | I34: =SUMIF('dali wip-fg'!A:A,A34,'dali wip-fg'!F:F) -> 0 | J34: =SUMIF('dali wip-fg'!A:A,C34,'dali wip-fg'!F:F) -> 203 | K34: =+I34+J34 -> 203 | L34: =+K34/H34 -> 24.457831 | M34: ให้ดู WIP DAY | N34: =IF(L34<6,"แดง",IF(AND(L34>=7,L34<=10),"เหลือง","อื่นๆ")) -> อื่นๆ | O34: =SUMIFS(ord!$F:$F, ord!$C:$C,'check dali wipday'!A34, ord!$G:$G, ">="&DATE(2025,1,1), ord!$G:$G, "<="&$P$2) -> 0 | P34: =+K34-O34 -> 203 | Q34: ให้ดู WIP DAY
A35: 8983943851 | B35: F-RP | C35: 8983943850;A | D35: =SUMIF(fo!C:C,A35,fo!U:U) -> 51 | E35: =SUMIF(fo!C:C,A35,fo!T:T) -> 51 | F35: =SUMIF(fo!C:C,A35,fo!Z:Z) -> 7 | G35: =SUM(E35:F35) -> 58 | H35: =G35/$L$3 -> 2.9 | I35: =SUMIF('dali wip-fg'!A:A,A35,'dali wip-fg'!F:F) -> 54 | J35: =SUMIF('dali wip-fg'!A:A,C35,'dali wip-fg'!F:F) -> 400 | K35: =+I35+J35 -> 454 | L35: =+K35/H35 -> 156.55172 | M35: ให้ดู WIP DAY | N35: =IF(L35<6,"แดง",IF(AND(L35>=7,L35<=10),"เหลือง","อื่นๆ")) -> อื่นๆ | O35: =SUMIFS(ord!$F:$F, ord!$C:$C,'check dali wipday'!A35, ord!$G:$G, ">="&DATE(2025,1,1), ord!$G:$G, "<="&$P$2) -> 56 | P35: =+K35-O35 -> 398 | Q35: ให้ดู WIP DAY
A36: 8983943862 | B36: F-RP | C36: 8983943860;A | D36: =SUMIF(fo!C:C,A36,fo!U:U) -> 1268 | E36: =SUMIF(fo!C:C,A36,fo!T:T) -> 6997 | F36: =SUMIF(fo!C:C,A36,fo!Z:Z) -> 1812 | G36: =SUM(E36:F36) -> 8809 | H36: =G36/$L$3 -> 440.45 | I36: =SUMIF('dali wip-fg'!A:A,A36,'dali wip-fg'!F:F) -> 679 | J36: =SUMIF('dali wip-fg'!A:A,C36,'dali wip-fg'!F:F) -> 2050 | K36: =+I36+J36 -> 2729 | L36: =+K36/H36 -> 6.195936 | M36: ให้ดู WIP DAY | N36: =IF(L36<6,"แดง",IF(AND(L36>=7,L36<=10),"เหลือง","อื่นๆ")) -> อื่นๆ | O36: =SUMIFS(ord!$F:$F, ord!$C:$C,'check dali wipday'!A36, ord!$G:$G, ">="&DATE(2025,1,1), ord!$G:$G, "<="&$P$2) -> 1438 | P36: =+K36-O36 -> 1291 | Q36: ให้ดู WIP DAY
A37: 8983947931 | B37: F-EM | C37: 8983947931;A | D37: =SUMIF(fo!C:C,A37,fo!U:U) -> 4973 | E37: =SUMIF(fo!C:C,A37,fo!T:T) -> 17986 | F37: =SUMIF(fo!C:C,A37,fo!Z:Z) -> 5305 | G37: =SUM(E37:F37) -> 23291 | H37: =G37/$L$3 -> 1164.55 | I37: =SUMIF('dali wip-fg'!A:A,A37,'dali wip-fg'!F:F) -> 2235 | J37: =SUMIF('dali wip-fg'!A:A,C37,'dali wip-fg'!F:F) -> 5728 | K37: =+I37+J37 -> 7963 | L37: =+K37/H37 -> 6.8378344 | M37: ให้ดู WIP DAY | N37: =IF(L37<6,"แดง",IF(AND(L37>=7,L37<=10),"เหลือง","อื่นๆ")) -> อื่นๆ | O37: =SUMIFS(ord!$F:$F, ord!$C:$C,'check dali wipday'!A37, ord!$G:$G, ">="&DATE(2025,1,1), ord!$G:$G, "<="&$P$2) -> 4984 | P37: =+K37-O37 -> 2979 | Q37: ให้ดู WIP DAY
A38: 8983954210 | B38: F-EM | C38: 8983954210;A | D38: =SUMIF(fo!C:C,A38,fo!U:U) -> 485 | E38: =SUMIF(fo!C:C,A38,fo!T:T) -> 4359 | F38: =SUMIF(fo!C:C,A38,fo!Z:Z) -> 514 | G38: =SUM(E38:F38) -> 4873 | H38: =G38/$L$3 -> 243.65 | I38: =SUMIF('dali wip-fg'!A:A,A38,'dali wip-fg'!F:F) -> 1696 | J38: =SUMIF('dali wip-fg'!A:A,C38,'dali wip-fg'!F:F) -> 5388 | K38: =+I38+J38 -> 7084 | L38: =SUBTOTAL(9,L34:L37) -> 194.04333 | M38: ให้ดู WIP DAY | N38: =IF(L38<6,"แดง",IF(AND(L38>=7,L38<=10),"เหลือง","อื่นๆ")) -> อื่นๆ | O38: =SUMIFS(ord!$F:$F, ord!$C:$C,'check dali wipday'!A38, ord!$G:$G, ">="&DATE(2025,1,1), ord!$G:$G, "<="&$P$2) -> 870 | P38: =+K38-O38 -> 6214 | Q38: ให้ดู WIP DAY
A39: 22800055900000 | B39: F-FLOAT | C39: 0228-00055-90;A2 | D39: =SUMIF(fo!C:C,A39,fo!U:U) -> 0 | E39: =SUMIF(fo!C:C,A39,fo!T:T) -> 0 | F39: =SUMIF(fo!C:C,A39,fo!Z:Z) -> 0 | G39: =SUM(E39:F39) -> 0 | H39: =G39/$L$3 -> 0 | I39: =SUMIF('dali wip-fg'!A:A,A39,'dali wip-fg'!F:F) -> 0 | J39: =SUMIF('dali wip-fg'!A:A,C39,'dali wip-fg'!F:F) -> 0 | K39: =+I39+J39 -> 0 | L39: =+K39/H39 -> #DIV/0! | N39: =IF(L39<6,"แดง",IF(AND(L39>=7,L39<=10),"เหลือง","อื่นๆ")) -> #DIV/0! | O39: =SUMIFS(ord!$F:$F, ord!$C:$C,'check dali wipday'!A39, ord!$G:$G, ">="&DATE(2025,1,1), ord!$G:$G, "<="&$P$2) -> 0 | P39: =+K39-O39 -> 0 | Q39: =IF(_xlfn.MINIFS('ord check'!C:C,'ord check'!$A:$A,'check dali wipday'!A39,'ord check'!J:J,"<0")=0,"",_xlfn.MINIFS('ord check'!C:C,'ord check'!A:A,'check dali wipday'!A39,'ord check'!J:J,"<0"))
A40: 22800059900000 | B40: F-FLOAT | C40: 0228-0008-00;A2 | D40: =SUMIF(fo!C:C,A40,fo!U:U) -> 0 | E40: =SUMIF(fo!C:C,A40,fo!T:T) -> 0 | F40: =SUMIF(fo!C:C,A40,fo!Z:Z) -> 0 | G40: =SUM(E40:F40) -> 0 | H40: =G40/$L$3 -> 0 | I40: =SUMIF('dali wip-fg'!A:A,A40,'dali wip-fg'!F:F) -> 0 | J40: =SUMIF('dali wip-fg'!A:A,C40,'dali wip-fg'!F:F) -> 0 | K40: =+I40+J40 -> 0 | L40: =+K40/H40 -> #DIV/0! | N40: =IF(L40<6,"แดง",IF(AND(L40>=7,L40<=10),"เหลือง","อื่นๆ")) -> #DIV/0! | O40: =SUMIFS(ord!$F:$F, ord!$C:$C,'check dali wipday'!A40, ord!$G:$G, ">="&DATE(2025,1,1), ord!$G:$G, "<="&$P$2) -> 0 | P40: =+K40-O40 -> 0 | Q40: =IF(_xlfn.MINIFS('ord check'!C:C,'ord check'!$A:$A,'check dali wipday'!A40,'ord check'!J:J,"<0")=0,"",_xlfn.MINIFS('ord check'!C:C,'ord check'!A:A,'check dali wipday'!A40,'ord check'!J:J,"<0"))
A41: 0001-001 | B41: F-VAC | C41: 0001-001;A | D41: =SUMIF(fo!C:C,A41,fo!U:U) -> 0 | E41: =SUMIF(fo!C:C,A41,fo!T:T) -> 0 | F41: =SUMIF(fo!C:C,A41,fo!Z:Z) -> 0 | G41: =SUM(E41:F41) -> 0 | H41: =G41/$L$3 -> 0 | I41: =SUMIF('dali wip-fg'!A:A,A41,'dali wip-fg'!F:F) -> 0 | J41: =SUMIF('dali wip-fg'!A:A,C41,'dali wip-fg'!F:F) -> 0 | K41: =+I41+J41 -> 0 | L41: =+K41/H41 -> #DIV/0! | N41: =IF(L41<6,"แดง",IF(AND(L41>=7,L41<=10),"เหลือง","อื่นๆ")) -> #DIV/0! | O41: =SUMIFS(ord!$F:$F, ord!$C:$C,'check dali wipday'!A41, ord!$G:$G, ">="&DATE(2025,1,1), ord!$G:$G, "<="&$P$2) -> 0 | P41: =+K41-O41 -> 0 | Q41: =IF(_xlfn.MINIFS('ord check'!C:C,'ord check'!$A:$A,'check dali wipday'!A41,'ord check'!J:J,"<0")=0,"",_xlfn.MINIFS('ord check'!C:C,'ord check'!A:A,'check dali wipday'!A41,'ord check'!J:J,"<0"))
A42: 0108-I190-GASKET | B42: F-RP | C42: 0108-I190-GASKET;A | D42: =SUMIF(fo!C:C,A42,fo!U:U) -> 0 | E42: =SUMIF(fo!C:C,A42,fo!T:T) -> 0 | F42: =SUMIF(fo!C:C,A42,fo!Z:Z) -> 0 | G42: =SUM(E42:F42) -> 0 | H42: =G42/$L$3 -> 0 | I42: =SUMIF('dali wip-fg'!A:A,A42,'dali wip-fg'!F:F) -> 0 | J42: =SUMIF('dali wip-fg'!A:A,C42,'dali wip-fg'!F:F) -> 0 | K42: =+I42+J42 -> 0 | L42: =+K42/H42 -> #DIV/0! | N42: =IF(L42<6,"แดง",IF(AND(L42>=7,L42<=10),"เหลือง","อื่นๆ")) -> #DIV/0! | O42: =SUMIFS(ord!$F:$F, ord!$C:$C,'check dali wipday'!A42, ord!$G:$G, ">="&DATE(2025,1,1), ord!$G:$G, "<="&$P$2) -> 0 | P42: =+K42-O42 -> 0 | Q42: =IF(_xlfn.MINIFS('ord check'!C:C,'ord check'!$A:$A,'check dali wipday'!A42,'ord check'!J:J,"<0")=0,"",_xlfn.MINIFS('ord check'!C:C,'ord check'!A:A,'check dali wipday'!A42,'ord check'!J:J,"<0"))
A43: 01-640280 | B43: F-RP | C43: 01-640280;A | D43: =SUMIF(fo!C:C,A43,fo!U:U) -> 0 | E43: =SUMIF(fo!C:C,A43,fo!T:T) -> 0 | F43: =SUMIF(fo!C:C,A43,fo!Z:Z) -> 0 | G43: =SUM(E43:F43) -> 0 | H43: =G43/$L$3 -> 0 | I43: =SUMIF('dali wip-fg'!A:A,A43,'dali wip-fg'!F:F) -> 0 | J43: =SUMIF('dali wip-fg'!A:A,C43,'dali wip-fg'!F:F) -> 0 | K43: =+I43+J43 -> 0 | L43: =+K43/H43 -> #DIV/0! | N43: =IF(L43<6,"แดง",IF(AND(L43>=7,L43<=10),"เหลือง","อื่นๆ")) -> #DIV/0! | O43: =SUMIFS(ord!$F:$F, ord!$C:$C,'check dali wipday'!A43, ord!$G:$G, ">="&DATE(2025,1,1), ord!$G:$G, "<="&$P$2) -> 0 | P43: =+K43-O43 -> 0 | Q43: =IF(_xlfn.MINIFS('ord check'!C:C,'ord check'!$A:$A,'check dali wipday'!A43,'ord check'!J:J,"<0")=0,"",_xlfn.MINIFS('ord check'!C:C,'ord check'!A:A,'check dali wipday'!A43,'ord check'!J:J,"<0"))
A44: 01-640312 | B44: F-RP | C44: 01-640312;A | D44: =SUMIF(fo!C:C,A44,fo!U:U) -> 0 | E44: =SUMIF(fo!C:C,A44,fo!T:T) -> 0 | F44: =SUMIF(fo!C:C,A44,fo!Z:Z) -> 0 | G44: =SUM(E44:F44) -> 0 | H44: =G44/$L$3 -> 0 | I44: =SUMIF('dali wip-fg'!A:A,A44,'dali wip-fg'!F:F) -> 0 | J44: =SUMIF('dali wip-fg'!A:A,C44,'dali wip-fg'!F:F) -> 0 | K44: =+I44+J44 -> 0 | L44: =+K44/H44 -> #DIV/0! | N44: =IF(L44<6,"แดง",IF(AND(L44>=7,L44<=10),"เหลือง","อื่นๆ")) -> #DIV/0! | O44: =SUMIFS(ord!$F:$F, ord!$C:$C,'check dali wipday'!A44, ord!$G:$G, ">="&DATE(2025,1,1), ord!$G:$G, "<="&$P$2) -> 0 | P44: =+K44-O44 -> 0 | Q44: =IF(_xlfn.MINIFS('ord check'!C:C,'ord check'!$A:$A,'check dali wipday'!A44,'ord check'!J:J,"<0")=0,"",_xlfn.MINIFS('ord check'!C:C,'ord check'!A:A,'check dali wipday'!A44,'ord check'!J:J,"<0"))
A45: 0208-28-320 | B45: F-EM | C45: 0208-28-320;A | D45: =SUMIF(fo!C:C,A45,fo!U:U) -> 0 | E45: =SUMIF(fo!C:C,A45,fo!T:T) -> 0 | F45: =SUMIF(fo!C:C,A45,fo!Z:Z) -> 0 | G45: =SUM(E45:F45) -> 0 | H45: =G45/$L$3 -> 0 | I45: =SUMIF('dali wip-fg'!A:A,A45,'dali wip-fg'!F:F) -> 0 | J45: =SUMIF('dali wip-fg'!A:A,C45,'dali wip-fg'!F:F) -> 0 | K45: =+I45+J45 -> 0 | L45: =+K45/H45 -> #DIV/0! | N45: =IF(L45<6,"แดง",IF(AND(L45>=7,L45<=10),"เหลือง","อื่นๆ")) -> #DIV/0! | O45: =SUMIFS(ord!$F:$F, ord!$C:$C,'check dali wipday'!A45, ord!$G:$G, ">="&DATE(2025,1,1), ord!$G:$G, "<="&$P$2) -> 0 | P45: =+K45-O45 -> 0 | Q45: =IF(_xlfn.MINIFS('ord check'!C:C,'ord check'!$A:$A,'check dali wipday'!A45,'ord check'!J:J,"<0")=0,"",_xlfn.MINIFS('ord check'!C:C,'ord check'!A:A,'check dali wipday'!A45,'ord check'!J:J,"<0"))
A46: 0228-00008-92-00 | B46: F-FLOAT | C46: 0228-0008-00;A2 | D46: =SUMIF(fo!C:C,A46,fo!U:U) -> 0 | E46: =SUMIF(fo!C:C,A46,fo!T:T) -> 0 | F46: =SUMIF(fo!C:C,A46,fo!Z:Z) -> 0 | G46: =SUM(E46:F46) -> 0 | H46: =G46/$L$3 -> 0 | I46: =SUMIF('dali wip-fg'!A:A,A46,'dali wip-fg'!F:F) -> 0 | J46: =SUMIF('dali wip-fg'!A:A,C46,'dali wip-fg'!F:F) -> 0 | K46: =+I46+J46 -> 0 | L46: =+K46/H46 -> #DIV/0! | N46: =IF(L46<6,"แดง",IF(AND(L46>=7,L46<=10),"เหลือง","อื่นๆ")) -> #DIV/0! | O46: =SUMIFS(ord!$F:$F, ord!$C:$C,'check dali wipday'!A46, ord!$G:$G, ">="&DATE(2025,1,1), ord!$G:$G, "<="&$P$2) -> 0 | P46: =+K46-O46 -> 0 | Q46: =IF(_xlfn.MINIFS('ord check'!C:C,'ord check'!$A:$A,'check dali wipday'!A46,'ord check'!J:J,"<0")=0,"",_xlfn.MINIFS('ord check'!C:C,'ord check'!A:A,'check dali wipday'!A46,'ord check'!J:J,"<0"))
A47: 0228-00019-9000 | B47: F-FLOAT | C47: 0228-00019-9000;A2 | D47: =SUMIF(fo!C:C,A47,fo!U:U) -> 0 | E47: =SUMIF(fo!C:C,A47,fo!T:T) -> 0 | F47: =SUMIF(fo!C:C,A47,fo!Z:Z) -> 0 | G47: =SUM(E47:F47) -> 0 | H47: =G47/$L$3 -> 0 | I47: =SUMIF('dali wip-fg'!A:A,A47,'dali wip-fg'!F:F) -> 0 | J47: =SUMIF('dali wip-fg'!A:A,C47,'dali wip-fg'!F:F) -> 0 | K47: =+I47+J47 -> 0 | L47: =+K47/H47 -> #DIV/0! | N47: =IF(L47<6,"แดง",IF(AND(L47>=7,L47<=10),"เหลือง","อื่นๆ")) -> #DIV/0! | O47: =SUMIFS(ord!$F:$F, ord!$C:$C,'check dali wipday'!A47, ord!$G:$G, ">="&DATE(2025,1,1), ord!$G:$G, "<="&$P$2) -> 0 | P47: =+K47-O47 -> 0 | Q47: =IF(_xlfn.MINIFS('ord check'!C:C,'ord check'!$A:$A,'check dali wipday'!A47,'ord check'!J:J,"<0")=0,"",_xlfn.MINIFS('ord check'!C:C,'ord check'!A:A,'check dali wipday'!A47,'ord check'!J:J,"<0"))
A48: 0228000199000K | B48: F-FLOAT | C48: 0228-00019-9000;A2 | D48: =SUMIF(fo!C:C,A48,fo!U:U) -> 0 | E48: =SUMIF(fo!C:C,A48,fo!T:T) -> 0 | F48: =SUMIF(fo!C:C,A48,fo!Z:Z) -> 0 | G48: =SUM(E48:F48) -> 0 | H48: =G48/$L$3 -> 0 | I48: =SUMIF('dali wip-fg'!A:A,A48,'dali wip-fg'!F:F) -> 0 | J48: =SUMIF('dali wip-fg'!A:A,C48,'dali wip-fg'!F:F) -> 0 | K48: =+I48+J48 -> 0 | L48: =+K48/H48 -> #DIV/0! | N48: =IF(L48<6,"แดง",IF(AND(L48>=7,L48<=10),"เหลือง","อื่นๆ")) -> #DIV/0! | O48: =SUMIFS(ord!$F:$F, ord!$C:$C,'check dali wipday'!A48, ord!$G:$G, ">="&DATE(2025,1,1), ord!$G:$G, "<="&$P$2) -> 0 | P48: =+K48-O48 -> 0 | Q48: =IF(_xlfn.MINIFS('ord check'!C:C,'ord check'!$A:$A,'check dali wipday'!A48,'ord check'!J:J,"<0")=0,"",_xlfn.MINIFS('ord check'!C:C,'ord check'!A:A,'check dali wipday'!A48,'ord check'!J:J,"<0"))
A49: 0228000199000VN | B49: F-FLOAT | C49: 0228-00019-9000;A2 | D49: =SUMIF(fo!C:C,A49,fo!U:U) -> 0 | E49: =SUMIF(fo!C:C,A49,fo!T:T) -> 0 | F49: =SUMIF(fo!C:C,A49,fo!Z:Z) -> 0 | G49: =SUM(E49:F49) -> 0 | H49: =G49/$L$3 -> 0 | I49: =SUMIF('dali wip-fg'!A:A,A49,'dali wip-fg'!F:F) -> 0 | J49: =SUMIF('dali wip-fg'!A:A,C49,'dali wip-fg'!F:F) -> 0 | K49: =+I49+J49 -> 0 | L49: =+K49/H49 -> #DIV/0! | N49: =IF(L49<6,"แดง",IF(AND(L49>=7,L49<=10),"เหลือง","อื่นๆ")) -> #DIV/0! | O49: =SUMIFS(ord!$F:$F, ord!$C:$C,'check dali wipday'!A49, ord!$G:$G, ">="&DATE(2025,1,1), ord!$G:$G, "<="&$P$2) -> 0 | P49: =+K49-O49 -> 0 | Q49: =IF(_xlfn.MINIFS('ord check'!C:C,'ord check'!$A:$A,'check dali wipday'!A49,'ord check'!J:J,"<0")=0,"",_xlfn.MINIFS('ord check'!C:C,'ord check'!A:A,'check dali wipday'!A49,'ord check'!J:J,"<0"))
A50: 0228000199C0002 | B50: F-FLOAT | C50: 0228-00019-9000;A2 | D50: =SUMIF(fo!C:C,A50,fo!U:U) -> 0 | E50: =SUMIF(fo!C:C,A50,fo!T:T) -> 0 | F50: =SUMIF(fo!C:C,A50,fo!Z:Z) -> 0 | G50: =SUM(E50:F50) -> 0 | H50: =G50/$L$3 -> 0 | I50: =SUMIF('dali wip-fg'!A:A,A50,'dali wip-fg'!F:F) -> 0 | J50: =SUMIF('dali wip-fg'!A:A,C50,'dali wip-fg'!F:F) -> 0 | K50: =+I50+J50 -> 0 | L50: =+K50/H50 -> #DIV/0! | N50: =IF(L50<6,"แดง",IF(AND(L50>=7,L50<=10),"เหลือง","อื่นๆ")) -> #DIV/0! | O50: =SUMIFS(ord!$F:$F, ord!$C:$C,'check dali wipday'!A50, ord!$G:$G, ">="&DATE(2025,1,1), ord!$G:$G, "<="&$P$2) -> 0 | P50: =+K50-O50 -> 0 | Q50: =IF(_xlfn.MINIFS('ord check'!C:C,'ord check'!$A:$A,'check dali wipday'!A50,'ord check'!J:J,"<0")=0,"",_xlfn.MINIFS('ord check'!C:C,'ord check'!A:A,'check dali wipday'!A50,'ord check'!J:J,"<0"))
A51: 0228-00050-90-001 | B51: F-FLOAT | C51: 0228-00050-90;A2 | D51: =SUMIF(fo!C:C,A51,fo!U:U) -> 0 | E51: =SUMIF(fo!C:C,A51,fo!T:T) -> 0 | F51: =SUMIF(fo!C:C,A51,fo!Z:Z) -> 0 | G51: =SUM(E51:F51) -> 0 | H51: =G51/$L$3 -> 0 | I51: =SUMIF('dali wip-fg'!A:A,A51,'dali wip-fg'!F:F) -> 0 | J51: =SUMIF('dali wip-fg'!A:A,C51,'dali wip-fg'!F:F) -> 0 | K51: =+I51+J51 -> 0 | L51: =+K51/H51 -> #DIV/0! | N51: =IF(L51<6,"แดง",IF(AND(L51>=7,L51<=10),"เหลือง","อื่นๆ")) -> #DIV/0! | O51: =SUMIFS(ord!$F:$F, ord!$C:$C,'check dali wipday'!A51, ord!$G:$G, ">="&DATE(2025,1,1), ord!$G:$G, "<="&$P$2) -> 0 | P51: =+K51-O51 -> 0 | Q51: =IF(_xlfn.MINIFS('ord check'!C:C,'ord check'!$A:$A,'check dali wipday'!A51,'ord check'!J:J,"<0")=0,"",_xlfn.MINIFS('ord check'!C:C,'ord check'!A:A,'check dali wipday'!A51,'ord check'!J:J,"<0"))
A52: 0228000509C0001 | B52: F-FLOAT | C52: 0228-00050-90;A2 | D52: =SUMIF(fo!C:C,A52,fo!U:U) -> 0 | E52: =SUMIF(fo!C:C,A52,fo!T:T) -> 0 | F52: =SUMIF(fo!C:C,A52,fo!Z:Z) -> 0 | G52: =SUM(E52:F52) -> 0 | H52: =G52/$L$3 -> 0 | I52: =SUMIF('dali wip-fg'!A:A,A52,'dali wip-fg'!F:F) -> 0 | J52: =SUMIF('dali wip-fg'!A:A,C52,'dali wip-fg'!F:F) -> 0 | K52: =+I52+J52 -> 0 | L52: =+K52/H52 -> #DIV/0! | N52: =IF(L52<6,"แดง",IF(AND(L52>=7,L52<=10),"เหลือง","อื่นๆ")) -> #DIV/0! | O52: =SUMIFS(ord!$F:$F, ord!$C:$C,'check dali wipday'!A52, ord!$G:$G, ">="&DATE(2025,1,1), ord!$G:$G, "<="&$P$2) -> 0 | P52: =+K52-O52 -> 0 | Q52: =IF(_xlfn.MINIFS('ord check'!C:C,'ord check'!$A:$A,'check dali wipday'!A52,'ord check'!J:J,"<0")=0,"",_xlfn.MINIFS('ord check'!C:C,'ord check'!A:A,'check dali wipday'!A52,'ord check'!J:J,"<0"))
... A132: 11220-71L00 | B132: F-EM | C132: 11220-71L00;A | D132: =SUMIF(fo!C:C,A132,fo!U:U) -> 0 | E132: =SUMIF(fo!C:C,A132,fo!T:T) -> 0 | F132: =SUMIF(fo!C:C,A132,fo!Z:Z) -> 0 | G132: =SUM(E132:F132) -> 0 | H132: =G132/$L$3 -> 0 | I132: =SUMIF('dali wip-fg'!A:A,A132,'dali wip-fg'!F:F) -> 0 | J132: =SUMIF('dali wip-fg'!A:A,C132,'dali wip-fg'!F:F) -> 0 | K132: =+I132+J132 -> 0 | L132: =+K132/H132 -> #DIV/0! | N132: =IF(L132<6,"แดง",IF(AND(L132>=7,L132<=10),"เหลือง","อื่นๆ")) -> #DIV/0! | O132: =SUMIFS(ord!$F:$F, ord!$C:$C,'check dali wipday'!A132, ord!$G:$G, ">="&DATE(2025,1,1), ord!$G:$G, "<="&$P$2) -> 0 | P132: =+K132-O132 -> 0 | Q132: =IF(_xlfn.MINIFS('ord check'!C:C,'ord check'!$A:$A,'check dali wipday'!A132,'ord check'!J:J,"<0")=0,"",_xlfn.MINIFS('ord check'!C:C,'ord check'!A:A,'check dali wipday'!A132,'ord check'!J:J,"<0"))
...

Sheet ord check
A1: SAP Mat. | B1: Outstd.Base Qty | C1: Dlv. Date | F1: semi | G1: fg | H1: wip | I1: total | J1: Balance | N1: Material | O1: Matl group | P1: Component
A2: =ord!C2 -> 73525-SWA-0000 | B2: =ord!F2 -> 20 | C2: =ord!G2 -> 46241 | F2: =VLOOKUP(A2,N:P,3,0) -> #N/A | G2: =SUMIF('dali wip-fg'!A:A,A2,'dali wip-fg'!F:F) -> 17 | H2: =SUMIF('dali wip-fg'!A:A,F2,'dali wip-fg'!F:F) -> 0 | I2: =SUM(G2:H2) -> 17 | J2: =IF(I2="","",IF(I2<>I1,I2-B2,J1-B2) ) -> -3 | N2: 19923 | O2: F-RP | P2: 19923;A
A3: =ord!C3 -> 75800-SNLA-T102 | B3: =ord!F3 -> 5 | C3: =ord!G3 -> 46248 | F3: =VLOOKUP(A3,N:P,3,0) -> 75800-SNLA-T102;A | G3: =SUMIF('dali wip-fg'!A:A,A3,'dali wip-fg'!F:F) -> 0 | H3: =SUMIF('dali wip-fg'!A:A,F3,'dali wip-fg'!F:F) -> 247 | I3: =SUM(G3:H3) -> 247 | J3: =IF(I3="","",IF(I3<>I2,I3-B3,J2-B3) ) -> 242 | N3: 1182003 | O3: F-RPM | P3: 1182003;A
A4: =ord!C4 -> 75800-SNLA-T102 | B4: =ord!F4 -> 4 | C4: =ord!G4 -> 46248 | F4: =VLOOKUP(A4,N:P,3,0) -> 75800-SNLA-T102;A | G4: =SUMIF('dali wip-fg'!A:A,A4,'dali wip-fg'!F:F) -> 0 | H4: =SUMIF('dali wip-fg'!A:A,F4,'dali wip-fg'!F:F) -> 247 | I4: =SUM(G4:H4) -> 247 | J4: =IF(I4="","",IF(I4<>I3,I4-B4,J3-B4) ) -> 238 | N4: 1182011 | O4: F-EM | P4: 1182011;A
A5: =ord!C5 -> 75800-SNLA-T102 | B5: =ord!F5 -> 4 | C5: =ord!G5 -> 46255 | F5: =VLOOKUP(A5,N:P,3,0) -> 75800-SNLA-T102;A | G5: =SUMIF('dali wip-fg'!A:A,A5,'dali wip-fg'!F:F) -> 0 | H5: =SUMIF('dali wip-fg'!A:A,F5,'dali wip-fg'!F:F) -> 247 | I5: =SUM(G5:H5) -> 247 | J5: =IF(I5="","",IF(I5<>I4,I5-B5,J4-B5) ) -> 234 | N5: 1184469 | O5: F-RPM | P5: 1184469;A
A6: =ord!C6 -> 75800-SNLA-T102 | B6: =ord!F6 -> 4 | C6: =ord!G6 -> 46262 | F6: =VLOOKUP(A6,N:P,3,0) -> 75800-SNLA-T102;A | G6: =SUMIF('dali wip-fg'!A:A,A6,'dali wip-fg'!F:F) -> 0 | H6: =SUMIF('dali wip-fg'!A:A,F6,'dali wip-fg'!F:F) -> 247 | I6: =SUM(G6:H6) -> 247 | J6: =IF(I6="","",IF(I6<>I5,I6-B6,J5-B6) ) -> 230 | N6: 1189300 | O6: F-RPM | P6: 1189300;A
A7: =ord!C7 -> 75810-SNLA-T102 | B7: =ord!F7 -> 3 | C7: =ord!G7 -> 46255 | F7: =VLOOKUP(A7,N:P,3,0) -> 75810-SNLA-T102;A | G7: =SUMIF('dali wip-fg'!A:A,A7,'dali wip-fg'!F:F) -> 0 | H7: =SUMIF('dali wip-fg'!A:A,F7,'dali wip-fg'!F:F) -> 174 | I7: =SUM(G7:H7) -> 174 | J7: =IF(I7="","",IF(I7<>I6,I7-B7,J6-B7) ) -> 171 | N7: 1189988 | O7: F-RPM | P7: 1189988;A
A8: =ord!C8 -> 75810-SNLA-T102 | B8: =ord!F8 -> 3 | C8: =ord!G8 -> 46262 | F8: =VLOOKUP(A8,N:P,3,0) -> 75810-SNLA-T102;A | G8: =SUMIF('dali wip-fg'!A:A,A8,'dali wip-fg'!F:F) -> 0 | H8: =SUMIF('dali wip-fg'!A:A,F8,'dali wip-fg'!F:F) -> 174 | I8: =SUM(G8:H8) -> 174 | J8: =IF(I8="","",IF(I8<>I7,I8-B8,J7-B8) ) -> 168 | N8: 5848516 | P8: 5848516;A
A9: =ord!C9 -> 75830-SNLA-T101 | B9: =ord!F9 -> 2 | C9: =ord!G9 -> 46255 | F9: =VLOOKUP(A9,N:P,3,0) -> 75830-SNLA-T101;A | G9: =SUMIF('dali wip-fg'!A:A,A9,'dali wip-fg'!F:F) -> 0 | H9: =SUMIF('dali wip-fg'!A:A,F9,'dali wip-fg'!F:F) -> 45 | I9: =SUM(G9:H9) -> 45 | J9: =IF(I9="","",IF(I9<>I8,I9-B9,J8-B9) ) -> 43 | N9: 97215052 | O9: F-EM | P9: 97215052;A
A10: =ord!C10 -> 75830-SNLA-T101 | B10: =ord!F10 -> 3 | C10: =ord!G10 -> 46262 | F10: =VLOOKUP(A10,N:P,3,0) -> 75830-SNLA-T101;A | G10: =SUMIF('dali wip-fg'!A:A,A10,'dali wip-fg'!F:F) -> 0 | H10: =SUMIF('dali wip-fg'!A:A,F10,'dali wip-fg'!F:F) -> 45 | I10: =SUM(G10:H10) -> 45 | J10: =IF(I10="","",IF(I10<>I9,I10-B10,J9-B10) ) -> 40 | N10: 97235925 | O10: F-EM | P10: 97235925;A
A11: =ord!C11 -> 4PB30948-1 | B11: =ord!F11 -> 500 | C11: =ord!G11 -> 46248 | F11: =VLOOKUP(A11,N:P,3,0) -> 205X210-C60;A | G11: =SUMIF('dali wip-fg'!A:A,A11,'dali wip-fg'!F:F) -> 500 | H11: =SUMIF('dali wip-fg'!A:A,F11,'dali wip-fg'!F:F) -> 64 | I11: =SUM(G11:H11) -> 564 | J11: =IF(I11="","",IF(I11<>I10,I11-B11,J10-B11) ) -> 64 | N11: 97946549 | O11: F-EM | P11: 97946549;A
A12: =ord!C12 -> 1G957-1452-1 | B12: =ord!F12 -> 2000 | C12: =ord!G12 -> 46253 | F12: =VLOOKUP(A12,N:P,3,0) -> 1G957-1452-1;A | G12: =SUMIF('dali wip-fg'!A:A,A12,'dali wip-fg'!F:F) -> 6000 | H12: =SUMIF('dali wip-fg'!A:A,F12,'dali wip-fg'!F:F) -> 1020 | I12: =SUM(G12:H12) -> 7020 | J12: =IF(I12="","",IF(I12<>I11,I12-B12,J11-B12) ) -> 5020 | N12: 97946803 | O12: F-EM | P12: 97946803;A
A13: =ord!C13 -> 1J630-69F-A000 | B13: =ord!F13 -> 60 | C13: =ord!G13 -> 46248 | F13: =VLOOKUP(A13,N:P,3,0) -> 1J630-69F-A000;A | G13: =SUMIF('dali wip-fg'!A:A,A13,'dali wip-fg'!F:F) -> 762 | H13: =SUMIF('dali wip-fg'!A:A,F13,'dali wip-fg'!F:F) -> 1215 | I13: =SUM(G13:H13) -> 1977 | J13: =IF(I13="","",IF(I13<>I12,I13-B13,J12-B13) ) -> 1917 | N13: 98181937 | O13: F-RP | P13: 98181937;A
A14: =ord!C14 -> 1J630-69F-A000 | B14: =ord!F14 -> 120 | C14: =ord!G14 -> 46248 | F14: =VLOOKUP(A14,N:P,3,0) -> 1J630-69F-A000;A | G14: =SUMIF('dali wip-fg'!A:A,A14,'dali wip-fg'!F:F) -> 762 | H14: =SUMIF('dali wip-fg'!A:A,F14,'dali wip-fg'!F:F) -> 1215 | I14: =SUM(G14:H14) -> 1977 | J14: =IF(I14="","",IF(I14<>I13,I14-B14,J13-B14) ) -> 1797 | N14: 322954801 | O14: F-RP | P14: B-2400;TRD060S
A15: =ord!C15 -> 1J630-69F-A000 | B15: =ord!F15 -> 120 | C15: =ord!G15 -> 46251 | F15: =VLOOKUP(A15,N:P,3,0) -> 1J630-69F-A000;A | G15: =SUMIF('dali wip-fg'!A:A,A15,'dali wip-fg'!F:F) -> 762 | H15: =SUMIF('dali wip-fg'!A:A,F15,'dali wip-fg'!F:F) -> 1215 | I15: =SUM(G15:H15) -> 1977 | J15: =IF(I15="","",IF(I15<>I14,I15-B15,J14-B15) ) -> 1677 | N15: 334516500 | O15: F-RP | P15: 334516500;A
A16: =ord!C16 -> 1J630-69F-A000 | B16: =ord!F16 -> 60 | C16: =ord!G16 -> 46252 | F16: =VLOOKUP(A16,N:P,3,0) -> 1J630-69F-A000;A | G16: =SUMIF('dali wip-fg'!A:A,A16,'dali wip-fg'!F:F) -> 762 | H16: =SUMIF('dali wip-fg'!A:A,F16,'dali wip-fg'!F:F) -> 1215 | I16: =SUM(G16:H16) -> 1977 | J16: =IF(I16="","",IF(I16<>I15,I16-B16,J15-B16) ) -> 1617 | N16: 975579810 | P16: 975579810;A
A17: =ord!C17 -> 1J630-69F-A000 | B17: =ord!F17 -> 60 | C17: =ord!G17 -> 46253 | F17: =VLOOKUP(A17,N:P,3,0) -> 1J630-69F-A000;A | G17: =SUMIF('dali wip-fg'!A:A,A17,'dali wip-fg'!F:F) -> 762 | H17: =SUMIF('dali wip-fg'!A:A,F17,'dali wip-fg'!F:F) -> 1215 | I17: =SUM(G17:H17) -> 1977 | J17: =IF(I17="","",IF(I17<>I16,I17-B17,J16-B17) ) -> 1557 | N17: 1209421300 | P17: 1209421300;A
A18: =ord!C18 -> 1J630-69F-A000 | B18: =ord!F18 -> 120 | C18: =ord!G18 -> 46254 | F18: =VLOOKUP(A18,N:P,3,0) -> 1J630-69F-A000;A | G18: =SUMIF('dali wip-fg'!A:A,A18,'dali wip-fg'!F:F) -> 762 | H18: =SUMIF('dali wip-fg'!A:A,F18,'dali wip-fg'!F:F) -> 1215 | I18: =SUM(G18:H18) -> 1977 | J18: =IF(I18="","",IF(I18<>I17,I18-B18,J17-B18) ) -> 1437 | N18: 1511720971 | O18: F-RPM | P18: 1511720971;A
A19: =ord!C19 -> 1J630-69F-A000 | B19: =ord!F19 -> 60 | C19: =ord!G19 -> 46255 | F19: =VLOOKUP(A19,N:P,3,0) -> 1J630-69F-A000;A | G19: =SUMIF('dali wip-fg'!A:A,A19,'dali wip-fg'!F:F) -> 762 | H19: =SUMIF('dali wip-fg'!A:A,F19,'dali wip-fg'!F:F) -> 1215 | I19: =SUM(G19:H19) -> 1977 | J19: =IF(I19="","",IF(I19<>I18,I19-B19,J18-B19) ) -> 1377 | N19: 1609538141 | O19: F-RP | P19: 1609538141;A
A20: =ord!C20 -> 1J630-69F-A000 | B20: =ord!F20 -> 60 | C20: =ord!G20 -> 46260 | F20: =VLOOKUP(A20,N:P,3,0) -> 1J630-69F-A000;A | G20: =SUMIF('dali wip-fg'!A:A,A20,'dali wip-fg'!F:F) -> 762 | H20: =SUMIF('dali wip-fg'!A:A,F20,'dali wip-fg'!F:F) -> 1215 | I20: =SUM(G20:H20) -> 1977 | J20: =IF(I20="","",IF(I20<>I19,I20-B20,J19-B20) ) -> 1317 | N20: 1615085102 | O20: F-RP | P20: 1615085102;A
A21: =ord!C21 -> 1J630-69F-A000 | B21: =ord!F21 -> 60 | C21: =ord!G21 -> 46261 | F21: =VLOOKUP(A21,N:P,3,0) -> 1J630-69F-A000;A | G21: =SUMIF('dali wip-fg'!A:A,A21,'dali wip-fg'!F:F) -> 762 | H21: =SUMIF('dali wip-fg'!A:A,F21,'dali wip-fg'!F:F) -> 1215 | I21: =SUM(G21:H21) -> 1977 | J21: =IF(I21="","",IF(I21<>I20,I21-B21,J20-B21) ) -> 1257 | N21: 5240189650 | O21: F-RP | P21: 5240189650;A
A22: =ord!C22 -> 1J670-69F-A000 | B22: =ord!F22 -> 60 | C22: =ord!G22 -> 46248 | F22: =VLOOKUP(A22,N:P,3,0) -> 1J670-69F-A000;A | G22: =SUMIF('dali wip-fg'!A:A,A22,'dali wip-fg'!F:F) -> 699 | H22: =SUMIF('dali wip-fg'!A:A,F22,'dali wip-fg'!F:F) -> 135 | I22: =SUM(G22:H22) -> 834 | J22: =IF(I22="","",IF(I22<>I21,I22-B22,J21-B22) ) -> 774 | N22: 5335025380 | O22: F-RP | P22: 5335025380;A
A23: =ord!C23 -> 1J670-69F-A000 | B23: =ord!F23 -> 120 | C23: =ord!G23 -> 46248 | F23: =VLOOKUP(A23,N:P,3,0) -> 1J670-69F-A000;A | G23: =SUMIF('dali wip-fg'!A:A,A23,'dali wip-fg'!F:F) -> 699 | H23: =SUMIF('dali wip-fg'!A:A,F23,'dali wip-fg'!F:F) -> 135 | I23: =SUM(G23:H23) -> 834 | J23: =IF(I23="","",IF(I23<>I22,I23-B23,J22-B23) ) -> 654 | N23: 5345033750 | O23: F-RP | P23: 226-209-007;A
A24: =ord!C24 -> 1J670-69F-A000 | B24: =ord!F24 -> 120 | C24: =ord!G24 -> 46251 | F24: =VLOOKUP(A24,N:P,3,0) -> 1J670-69F-A000;A | G24: =SUMIF('dali wip-fg'!A:A,A24,'dali wip-fg'!F:F) -> 699 | H24: =SUMIF('dali wip-fg'!A:A,F24,'dali wip-fg'!F:F) -> 135 | I24: =SUM(G24:H24) -> 834 | J24: =IF(I24="","",IF(I24<>I23,I24-B24,J23-B24) ) -> 534 | N24: 6508817700 | O24: F-RP | P24: 6508817700;A
A25: =ord!C25 -> 1J670-69F-A000 | B25: =ord!F25 -> 60 | C25: =ord!G25 -> 46252 | F25: =VLOOKUP(A25,N:P,3,0) -> 1J670-69F-A000;A | G25: =SUMIF('dali wip-fg'!A:A,A25,'dali wip-fg'!F:F) -> 699 | H25: =SUMIF('dali wip-fg'!A:A,F25,'dali wip-fg'!F:F) -> 135 | I25: =SUM(G25:H25) -> 834 | J25: =IF(I25="","",IF(I25<>I24,I25-B25,J24-B25) ) -> 474 | N25: 8519806800 | O25: F-VAC | P25: 8519806800;A
A26: =ord!C26 -> 1J670-69F-A000 | B26: =ord!F26 -> 60 | C26: =ord!G26 -> 46253 | F26: =VLOOKUP(A26,N:P,3,0) -> 1J670-69F-A000;A | G26: =SUMIF('dali wip-fg'!A:A,A26,'dali wip-fg'!F:F) -> 699 | H26: =SUMIF('dali wip-fg'!A:A,F26,'dali wip-fg'!F:F) -> 135 | I26: =SUM(G26:H26) -> 834 | J26: =IF(I26="","",IF(I26<>I25,I26-B26,J25-B26) ) -> 414 | N26: 8975007280 | O26: F-RP | P26: 8975007280;A
A27: =ord!C27 -> 1J670-69F-A000 | B27: =ord!F27 -> 120 | C27: =ord!G27 -> 46254 | F27: =VLOOKUP(A27,N:P,3,0) -> 1J670-69F-A000;A | G27: =SUMIF('dali wip-fg'!A:A,A27,'dali wip-fg'!F:F) -> 699 | H27: =SUMIF('dali wip-fg'!A:A,F27,'dali wip-fg'!F:F) -> 135 | I27: =SUM(G27:H27) -> 834 | J27: =IF(I27="","",IF(I27<>I26,I27-B27,J26-B27) ) -> 294 | N27: 8975385310 | O27: F-RP | P27: 8975385310;A
A28: =ord!C28 -> 1J670-69F-A000 | B28: =ord!F28 -> 60 | C28: =ord!G28 -> 46255 | F28: =VLOOKUP(A28,N:P,3,0) -> 1J670-69F-A000;A | G28: =SUMIF('dali wip-fg'!A:A,A28,'dali wip-fg'!F:F) -> 699 | H28: =SUMIF('dali wip-fg'!A:A,F28,'dali wip-fg'!F:F) -> 135 | I28: =SUM(G28:H28) -> 834 | J28: =IF(I28="","",IF(I28<>I27,I28-B28,J27-B28) ) -> 234 | N28: 8975579810 | O28: F-RPM | P28: 8975579810;A
A29: =ord!C29 -> 1J670-69F-A000 | B29: =ord!F29 -> 60 | C29: =ord!G29 -> 46260 | F29: =VLOOKUP(A29,N:P,3,0) -> 1J670-69F-A000;A | G29: =SUMIF('dali wip-fg'!A:A,A29,'dali wip-fg'!F:F) -> 699 | H29: =SUMIF('dali wip-fg'!A:A,F29,'dali wip-fg'!F:F) -> 135 | I29: =SUM(G29:H29) -> 834 | J29: =IF(I29="","",IF(I29<>I28,I29-B29,J28-B29) ) -> 174 | N29: 8978291420 | O29: F-RP | P29: 8978291420;A
A30: =ord!C30 -> 1J670-69F-A000 | B30: =ord!F30 -> 60 | C30: =ord!G30 -> 46261 | F30: =VLOOKUP(A30,N:P,3,0) -> 1J670-69F-A000;A | G30: =SUMIF('dali wip-fg'!A:A,A30,'dali wip-fg'!F:F) -> 699 | H30: =SUMIF('dali wip-fg'!A:A,F30,'dali wip-fg'!F:F) -> 135 | I30: =SUM(G30:H30) -> 834 | J30: =IF(I30="","",IF(I30<>I29,I30-B30,J29-B30) ) -> 114 | N30: 8983517840 | O30: F-RP | P30: 8983517840;A
A31: =ord!C31 -> 30E-73134-0000 | B31: =ord!F31 -> 2000 | C31: =ord!G31 -> 46241 | F31: =VLOOKUP(A31,N:P,3,0) -> #N/A | G31: =SUMIF('dali wip-fg'!A:A,A31,'dali wip-fg'!F:F) -> 2000 | H31: =SUMIF('dali wip-fg'!A:A,F31,'dali wip-fg'!F:F) -> 0 | I31: =SUM(G31:H31) -> 2000 | J31: =IF(I31="","",IF(I31<>I30,I31-B31,J30-B31) ) -> 0 | N31: 8983943812 | O31: F-RP | P31: 8983943810;A
A32: =ord!C32 -> J25-73134-0002 | B32: =ord!F32 -> 120000 | C32: =ord!G32 -> 46251 | F32: =VLOOKUP(A32,N:P,3,0) -> J25-73134-0002;A | G32: =SUMIF('dali wip-fg'!A:A,A32,'dali wip-fg'!F:F) -> 22500 | H32: =SUMIF('dali wip-fg'!A:A,F32,'dali wip-fg'!F:F) -> 158593 | I32: =SUM(G32:H32) -> 181093 | J32: =IF(I32="","",IF(I32<>I31,I32-B32,J31-B32) ) -> 61093 | N32: 8983943831 | O32: F-RP | P32: 8983943830;A
A33: =ord!C33 -> J25-73134-0002 | B33: =ord!F33 -> 96000 | C33: =ord!G33 -> 46253 | F33: =VLOOKUP(A33,N:P,3,0) -> J25-73134-0002;A | G33: =SUMIF('dali wip-fg'!A:A,A33,'dali wip-fg'!F:F) -> 22500 | H33: =SUMIF('dali wip-fg'!A:A,F33,'dali wip-fg'!F:F) -> 158593 | I33: =SUM(G33:H33) -> 181093 | J33: =IF(I33="","",IF(I33<>I32,I33-B33,J32-B33) ) -> -34907 | N33: 8983943851 | O33: F-RP | P33: 8983943850;A
A34: =ord!C34 -> J25-73134-0002 | B34: =ord!F34 -> 96000 | C34: =ord!G34 -> 46255 | F34: =VLOOKUP(A34,N:P,3,0) -> J25-73134-0002;A | G34: =SUMIF('dali wip-fg'!A:A,A34,'dali wip-fg'!F:F) -> 22500 | H34: =SUMIF('dali wip-fg'!A:A,F34,'dali wip-fg'!F:F) -> 158593 | I34: =SUM(G34:H34) -> 181093 | J34: =IF(I34="","",IF(I34<>I33,I34-B34,J33-B34) ) -> -130907 | N34: 8983943862 | O34: F-RP | P34: 8983943860;A
A35: =ord!C35 -> J25-73134-0002 | B35: =ord!F35 -> 80000 | C35: =ord!G35 -> 46258 | F35: =VLOOKUP(A35,N:P,3,0) -> J25-73134-0002;A | G35: =SUMIF('dali wip-fg'!A:A,A35,'dali wip-fg'!F:F) -> 22500 | H35: =SUMIF('dali wip-fg'!A:A,F35,'dali wip-fg'!F:F) -> 158593 | I35: =SUM(G35:H35) -> 181093 | J35: =IF(I35="","",IF(I35<>I34,I35-B35,J34-B35) ) -> -210907 | N35: 8983947931 | O35: F-EM | P35: 8983947931;A
A36: =ord!C36 -> J25-73134-0002 | B36: =ord!F36 -> 120000 | C36: =ord!G36 -> 46261 | F36: =VLOOKUP(A36,N:P,3,0) -> J25-73134-0002;A | G36: =SUMIF('dali wip-fg'!A:A,A36,'dali wip-fg'!F:F) -> 22500 | H36: =SUMIF('dali wip-fg'!A:A,F36,'dali wip-fg'!F:F) -> 158593 | I36: =SUM(G36:H36) -> 181093 | J36: =IF(I36="","",IF(I36<>I35,I36-B36,J35-B36) ) -> -330907 | N36: 8983954210 | O36: F-EM | P36: 8983954210;A
A37: =ord!C37 -> 42528-SMA-9010-Y1 | B37: =ord!F37 -> 10000 | C37: =ord!G37 -> 46248 | F37: =VLOOKUP(A37,N:P,3,0) -> 42528-SMA-9010;A | G37: =SUMIF('dali wip-fg'!A:A,A37,'dali wip-fg'!F:F) -> 19600 | H37: =SUMIF('dali wip-fg'!A:A,F37,'dali wip-fg'!F:F) -> 399002 | I37: =SUM(G37:H37) -> 418602 | J37: =IF(I37="","",IF(I37<>I36,I37-B37,J36-B37) ) -> 408602 | N37: 22800055900000 | O37: F-FLOAT | P37: 0228-00055-90;A2
A38: =ord!C38 -> 42528-SMA-9010-Y1 | B38: =ord!F38 -> 10000 | C38: =ord!G38 -> 46251 | F38: =VLOOKUP(A38,N:P,3,0) -> 42528-SMA-9010;A | G38: =SUMIF('dali wip-fg'!A:A,A38,'dali wip-fg'!F:F) -> 19600 | H38: =SUMIF('dali wip-fg'!A:A,F38,'dali wip-fg'!F:F) -> 399002 | I38: =SUM(G38:H38) -> 418602 | J38: =IF(I38="","",IF(I38<>I37,I38-B38,J37-B38) ) -> 398602 | N38: 22800059900000 | O38: F-FLOAT | P38: 0228-0008-00;A2
A39: =ord!C39 -> 42528-SMA-9010-Y1 | B39: =ord!F39 -> 10000 | C39: =ord!G39 -> 46255 | F39: =VLOOKUP(A39,N:P,3,0) -> 42528-SMA-9010;A | G39: =SUMIF('dali wip-fg'!A:A,A39,'dali wip-fg'!F:F) -> 19600 | H39: =SUMIF('dali wip-fg'!A:A,F39,'dali wip-fg'!F:F) -> 399002 | I39: =SUM(G39:H39) -> 418602 | J39: =IF(I39="","",IF(I39<>I38,I39-B39,J38-B39) ) -> 388602 | N39: 0001-001 | O39: F-VAC | P39: 0001-001;A
A40: =ord!C40 -> 897946-5490 | B40: =ord!F40 -> 30 | C40: =ord!G40 -> 46245 | F40: =VLOOKUP(A40,N:P,3,0) -> 897946-5490;A | G40: =SUMIF('dali wip-fg'!A:A,A40,'dali wip-fg'!F:F) -> 164 | H40: =SUMIF('dali wip-fg'!A:A,F40,'dali wip-fg'!F:F) -> 326 | I40: =SUM(G40:H40) -> 490 | J40: =IF(I40="","",IF(I40<>I39,I40-B40,J39-B40) ) -> 460 | N40: 0108-I190-GASKET | O40: F-RP | P40: 0108-I190-GASKET;A
...

Sheet dali wip-fg
A1: Material | B1: Plant | C1: Storage Location | D1: DF stor. loc. level | E1: Base Unit of Measure | F1: Unrestricted
A2: 97215052 | B2: 1200 | C2: 1201 | E2: PC | F2: 0
A3: 97235925 | B3: 1200 | C3: 1201 | E3: PC | F3: 1388
A4: 97235925 | B4: 1200 | C4: QC01 | E4: PC | F4: 480
A5: 97946549 | B5: 1200 | C5: 1201 | E5: PC | F5: 51
A6: 97946803 | B6: 1200 | C6: 1201 | E6: PC | F6: 0
A7: 1511720971 | B7: 1200 | C7: 1201 | E7: PC | F7: 10
A8: 1511720971 | B8: 1200 | C8: FG01 | E8: PC | F8: 60
A9: 1511720971 | B9: 1200 | C9: QC01 | E9: PC | F9: 204
A10: 6508817700 | B10: 1200 | C10: 1201 | E10: PC | F10: 67
A11: 7552008070 | B11: 1200 | C11: QC01 | E11: PC | F11: 30
A12: 7552296440 | B12: 1200 | C12: QC01 | E12: PC | F12: 115
A13: 7552296440 | B13: 1200 | C13: QC01 | E13: PC | F13: 55
... A35: 8983954210 | B35: 1200 | C35: FG01 | E35: PC | F35: 1500
A36: 0317-39-040;A | B36: 1200 | C36: QC01 | E36: PC | F36: 80
A37: 0317-39-050;A | B37: 1200 | C37: 1201 | E37: PC | F37: 88
A38: 10060-13980;A | B38: 1200 | C38: FG01 | E38: PC | F38: 1120
A39: 109337-0170 | B39: 1200 | C39: QC01 | E39: PC | F39: 6
A40: 109337-0170 | B40: 1200 | C40: PP01 | E40: PC | F40: 72
A41: 109337-0170 | B41: 1200 | C41: PP01 | E41: PC | F41: 216
A42: 109337-0170;A | B42: 1200 | C42: PP01 | E42: PC | F42: 1128
A43: 109337-0170;A | B43: 1200 | C43: 1201 | E43: PC | F43: 446
A44: 1093A044 | B44: 1200 | C44: QC01 | E44: PC | F44: 8
A45: 1093A044;A | B45: 1200 | C45: PP01 | E45: PC | F45: 186
A46: 1093A088 | B46: 1200 | C46: PSJ1 | E46: PC | F46: 100
A47: 1093A088;A | B47: 1200 | C47: QC01 | E47: PC | F47: 4
... A828: M-AFS-IRCT01 | B828: 1200 | C828: QC01 | E828: PC | F828: 1
A829: M9731-472-0B;A | B829: 1200 | E829: PC | F829: 63
A830: MB007023 | B830: 1200 | E830: PC | F830: 113
A831: MB111253 | B831: 1200 | E831: PC | F831: 115
A832: MB436365 | B832: 1200 | E832: PC | F832: 97
A833: MB436578;A | B833: 1200 | E833: PC | F833: 120
A834: MB513336 | B834: 1200 | E834: PC | F834: 3
A835: MB513386 | B835: 1200 | E835: PC | F835: 0
A836: MB513387 | B836: 1200 | E836: PC | F836: 106
A837: MB538926 | B837: 1200 | C837: PP01 | E837: PC | F837: 486
A838: MC421202 | B838: 1200 | E838: PC | F838: 1
A839: MC421202;A | B839: 1200 | C839: QC01 | E839: PC | F839: 42
A840: MD703280;A | B840: 1200 | C840: 1201 | E840: PC | F840: 428
A841: MN135024 | B841: 1200 | C841: 1201 | E841: PC | F841: 1
...

Sheet ord
A1: Customer | B1: Name | C1: SAP Mat. | D1: Cust.Mat. | E1: Base Qty | F1: Outstd.Base Qty | G1: Dlv. Date | H1: On Hand | I1: Wait Ins.(Unr) | J1: Group | K1: Create Date | L1: Order | S1: check | V1: semi | W1: fg | X1: wip | Y1: total | Z1: Balance
A2: 0000100013 | B2: ASIAN HONDA MOTOR CO.,LTD | C2: 73525-SWA-0000 | D2: 73525SWA000 spacer (60x1:8cyc | E2: 20 | F2: 20 | G2: 46241 | H2: 17 | I2: 0 | J2: F-PUNCH | K2: 46219 | L2: 0002240801 | S2: =VLOOKUP(C2,'check dali wipday'!A:A,1,0) -> #N/A | V2: =VLOOKUP(C2,'check dali wipday'!A:C,3,0) -> #N/A | W2: =SUMIF('dali wip-fg'!A:A,C2,'dali wip-fg'!F:F) -> 17 | X2: =SUMIF('dali wip-fg'!A:A,V2,'dali wip-fg'!F:F) -> 0 | Y2: =SUM(W2:X2) -> 17 | Z2: =IF(Y2="","",IF(Y2<>Y1,Y2-F2,Z1-F2) ) -> -3
A3: 0000100013 | B3: ASIAN HONDA MOTOR CO.,LTD | C3: 75800-SNLA-T102 | D3: 75800SNLT00 mud guard R FR | E3: 12 | F3: 5 | G3: 46248 | H3: 0 | I3: 0 | J3: F-RP | K3: 46219 | L3: 0002240813 | S3: =VLOOKUP(C3,'check dali wipday'!A:A,1,0) -> 75800-SNLA-T102 | V3: =VLOOKUP(C3,'check dali wipday'!A:C,3,0) -> 75800-SNLA-T102;A | W3: =SUMIF('dali wip-fg'!A:A,C3,'dali wip-fg'!F:F) -> 0 | X3: =SUMIF('dali wip-fg'!A:A,V3,'dali wip-fg'!F:F) -> 247 | Y3: =SUM(W3:X3) -> 247 | Z3: =IF(Y3="","",IF(Y3<>Y2,Y3-F3,Z2-F3) ) -> 242
A4: 0000100013 | B4: ASIAN HONDA MOTOR CO.,LTD | C4: 75800-SNLA-T102 | D4: 75800SNLT00 mud guard R FR | E4: 4 | F4: 4 | G4: 46248 | H4: 0 | I4: 0 | J4: F-RP | K4: 46219 | L4: 0002240815 | S4: =VLOOKUP(C4,'check dali wipday'!A:A,1,0) -> 75800-SNLA-T102 | V4: =VLOOKUP(C4,'check dali wipday'!A:C,3,0) -> 75800-SNLA-T102;A | W4: =SUMIF('dali wip-fg'!A:A,C4,'dali wip-fg'!F:F) -> 0 | X4: =SUMIF('dali wip-fg'!A:A,V4,'dali wip-fg'!F:F) -> 247 | Y4: =SUM(W4:X4) -> 247 | Z4: =IF(Y4="","",IF(Y4<>Y3,Y4-F4,Z3-F4) ) -> 238
A5: 0000100013 | B5: ASIAN HONDA MOTOR CO.,LTD | C5: 75800-SNLA-T102 | D5: 75800SNLT00 mud guard R FR | E5: 4 | F5: 4 | G5: 46255 | H5: 0 | I5: 0 | J5: F-RP | K5: 46219 | L5: 0002240821 | S5: =VLOOKUP(C5,'check dali wipday'!A:A,1,0) -> 75800-SNLA-T102 | V5: =VLOOKUP(C5,'check dali wipday'!A:C,3,0) -> 75800-SNLA-T102;A | W5: =SUMIF('dali wip-fg'!A:A,C5,'dali wip-fg'!F:F) -> 0 | X5: =SUMIF('dali wip-fg'!A:A,V5,'dali wip-fg'!F:F) -> 247 | Y5: =SUM(W5:X5) -> 247 | Z5: =IF(Y5="","",IF(Y5<>Y4,Y5-F5,Z4-F5) ) -> 234
A6: 0000100013 | B6: ASIAN HONDA MOTOR CO.,LTD | C6: 75800-SNLA-T102 | D6: 75800SNLT00 mud guard R FR | E6: 4 | F6: 4 | G6: 46262 | H6: 0 | I6: 0 | J6: F-RP | K6: 46219 | L6: 0002240826 | S6: =VLOOKUP(C6,'check dali wipday'!A:A,1,0) -> 75800-SNLA-T102 | V6: =VLOOKUP(C6,'check dali wipday'!A:C,3,0) -> 75800-SNLA-T102;A | W6: =SUMIF('dali wip-fg'!A:A,C6,'dali wip-fg'!F:F) -> 0 | X6: =SUMIF('dali wip-fg'!A:A,V6,'dali wip-fg'!F:F) -> 247 | Y6: =SUM(W6:X6) -> 247 | Z6: =IF(Y6="","",IF(Y6<>Y5,Y6-F6,Z5-F6) ) -> 230
A7: 0000100013 | B7: ASIAN HONDA MOTOR CO.,LTD | C7: 75810-SNLA-T102 | D7: 75810SNLT00 mud guard L FR | E7: 3 | F7: 3 | G7: 46255 | H7: 0 | I7: 0 | J7: F-RP | K7: 46219 | L7: 0002240821 | S7: =VLOOKUP(C7,'check dali wipday'!A:A,1,0) -> 75810-SNLA-T102 | V7: =VLOOKUP(C7,'check dali wipday'!A:C,3,0) -> 75810-SNLA-T102;A | W7: =SUMIF('dali wip-fg'!A:A,C7,'dali wip-fg'!F:F) -> 0 | X7: =SUMIF('dali wip-fg'!A:A,V7,'dali wip-fg'!F:F) -> 174 | Y7: =SUM(W7:X7) -> 174 | Z7: =IF(Y7="","",IF(Y7<>Y6,Y7-F7,Z6-F7) ) -> 171
A8: 0000100013 | B8: ASIAN HONDA MOTOR CO.,LTD | C8: 75810-SNLA-T102 | D8: 75810SNLT00 mud guard L FR | E8: 3 | F8: 3 | G8: 46262 | H8: 0 | I8: 0 | J8: F-RP | K8: 46219 | L8: 0002240826 | S8: =VLOOKUP(C8,'check dali wipday'!A:A,1,0) -> 75810-SNLA-T102 | V8: =VLOOKUP(C8,'check dali wipday'!A:C,3,0) -> 75810-SNLA-T102;A | W8: =SUMIF('dali wip-fg'!A:A,C8,'dali wip-fg'!F:F) -> 0 | X8: =SUMIF('dali wip-fg'!A:A,V8,'dali wip-fg'!F:F) -> 174 | Y8: =SUM(W8:X8) -> 174 | Z8: =IF(Y8="","",IF(Y8<>Y7,Y8-F8,Z7-F8) ) -> 168
A9: 0000100013 | B9: ASIAN HONDA MOTOR CO.,LTD | C9: 75830-SNLA-T101 | D9: 75830SNLT00 mud guard l rr | E9: 3 | F9: 2 | G9: 46255 | H9: 0 | I9: 0 | J9: F-RP | K9: 46219 | L9: 0002240821 | S9: =VLOOKUP(C9,'check dali wipday'!A:A,1,0) -> 75830-SNLA-T101 | V9: =VLOOKUP(C9,'check dali wipday'!A:C,3,0) -> 75830-SNLA-T101;A | W9: =SUMIF('dali wip-fg'!A:A,C9,'dali wip-fg'!F:F) -> 0 | X9: =SUMIF('dali wip-fg'!A:A,V9,'dali wip-fg'!F:F) -> 45 | Y9: =SUM(W9:X9) -> 45 | Z9: =IF(Y9="","",IF(Y9<>Y8,Y9-F9,Z8-F9) ) -> 43
A10: 0000100013 | B10: ASIAN HONDA MOTOR CO.,LTD | C10: 75830-SNLA-T101 | D10: 75830SNLT00 mud guard l rr | E10: 3 | F10: 3 | G10: 46262 | H10: 0 | I10: 0 | J10: F-RP | K10: 46219 | L10: 0002240826 | S10: =VLOOKUP(C10,'check dali wipday'!A:A,1,0) -> 75830-SNLA-T101 | V10: =VLOOKUP(C10,'check dali wipday'!A:C,3,0) -> 75830-SNLA-T101;A | W10: =SUMIF('dali wip-fg'!A:A,C10,'dali wip-fg'!F:F) -> 0 | X10: =SUMIF('dali wip-fg'!A:A,V10,'dali wip-fg'!F:F) -> 45 | Y10: =SUM(W10:X10) -> 45 | Z10: =IF(Y10="","",IF(Y10<>Y9,Y10-F10,Z9-F10) ) -> 40
A11: 0000100029 | B11: DAIKIN INDUSTRIES(THAILAND) LTD. | C11: 4PB30948-1 | D11: 4PB30948-1A INSULATION MATERI | E11: 500 | F11: 500 | G11: 46248 | H11: 500 | I11: 295 | J11: F-RP | K11: 46241 | L11: 0002247295 | S11: =VLOOKUP(C11,'check dali wipday'!A:A,1,0) -> 4PB30948-1 | V11: =VLOOKUP(C11,'check dali wipday'!A:C,3,0) -> 205X210-C60;A | W11: =SUMIF('dali wip-fg'!A:A,C11,'dali wip-fg'!F:F) -> 500 | X11: =SUMIF('dali wip-fg'!A:A,V11,'dali wip-fg'!F:F) -> 64 | Y11: =SUM(W11:X11) -> 564 | Z11: =IF(Y11="","",IF(Y11<>Y10,Y11-F11,Z10-F11) ) -> 64
A12: 0000100039 | B12: FUKUI KASEI (THAILAND)CO.,LTD. | C12: 1G957-1452-1 | D12: 1G957-1452-1 Gasket (2x2x1;6C | E12: 2000 | F12: 2000 | G12: 46253 | H12: 6000 | I12: 3251 | J12: F-RP | K12: 46210 | L12: 0002237964 | S12: =VLOOKUP(C12,'check dali wipday'!A:A,1,0) -> 1G957-1452-1 | V12: =VLOOKUP(C12,'check dali wipday'!A:C,3,0) -> 1G957-1452-1;A | W12: =SUMIF('dali wip-fg'!A:A,C12,'dali wip-fg'!F:F) -> 6000 | X12: =SUMIF('dali wip-fg'!A:A,V12,'dali wip-fg'!F:F) -> 1020 | Y12: =SUM(W12:X12) -> 7020 | Z12: =IF(Y12="","",IF(Y12<>Y11,Y12-F12,Z11-F12) ) -> 5020
A13: 0000100048 | B13: HONDA AUTOMOBILE (THAILAND) | C13: 1J630-69F-A000 | D13: 1J630-69F -A000 DUCT B,IPU IN | E13: 60 | F13: 60 | G13: 46248 | H13: 342 | I13: 510 | J13: F-RP | K13: 46234 | L13: 0002245041 | S13: =VLOOKUP(C13,'check dali wipday'!A:A,1,0) -> 1J630-69F-A000 | V13: =VLOOKUP(C13,'check dali wipday'!A:C,3,0) -> 1J630-69F-A000;A | W13: =SUMIF('dali wip-fg'!A:A,C13,'dali wip-fg'!F:F) -> 762 | X13: =SUMIF('dali wip-fg'!A:A,V13,'dali wip-fg'!F:F) -> 1215 | Y13: =SUM(W13:X13) -> 1977 | Z13: =IF(Y13="","",IF(Y13<>Y12,Y13-F13,Z12-F13) ) -> 1917
... A93: 0000100056 | B93: ISUZU MOTORS CO., (THAILAND) LTD. | C93: 5JX2228990 | D93: 898278-8110 DUCT ASM;A/CL OTL | E93: 45 | F93: 45 | G93: 46256 | H93: 59 | I93: 0 | J93: F-RP | K93: 46241 | L93: 0002247118 | S93: =VLOOKUP(C93,'check dali wipday'!A:A,1,0) -> 5JX2228990 | V93: =VLOOKUP(C93,'check dali wipday'!A:C,3,0) -> 5JX2228990;A | W93: =SUMIF('dali wip-fg'!A:A,C93,'dali wip-fg'!F:F) -> 89 | X93: =SUMIF('dali wip-fg'!A:A,V93,'dali wip-fg'!F:F) -> 1404 | Y93: =SUM(W93:X93) -> 1493 | Z93: =IF(Y93="","",IF(Y93<>Y92,Y93-F93,Z92-F93) ) -> 1013
A94: 0000100056 | B94: ISUZU MOTORS CO., (THAILAND) LTD. | C94: 8983943812 | D94: 8983943812 DUCT ASM;A/CL OTLT | E94: 45 | F94: 45 | G94: 46245 | H94: 114 | I94: 0 | J94: F-RP | K94: 46227 | L94: 0002243252 | S94: =VLOOKUP(C94,'check dali wipday'!A:A,1,0) -> 8983943812 | V94: =VLOOKUP(C94,'check dali wipday'!A:C,3,0) -> 8983943810;A | W94: =SUMIF('dali wip-fg'!A:A,C94,'dali wip-fg'!F:F) -> 194 | X94: =SUMIF('dali wip-fg'!A:A,V94,'dali wip-fg'!F:F) -> 1478 | Y94: =SUM(W94:X94) -> 1672 | Z94: =IF(Y94="","",IF(Y94<>Y93,Y94-F94,Z93-F94) ) -> 1627
A95: 0000100056 | B95: ISUZU MOTORS CO., (THAILAND) LTD. | C95: 8983943812 | D95: 8983943812 DUCT ASM;A/CL OTLT | E95: 60 | F95: 60 | G95: 46245 | H95: 114 | I95: 0 | J95: F-RP | K95: 46227 | L95: 0002243253 | S95: =VLOOKUP(C95,'check dali wipday'!A:A,1,0) -> 8983943812 | V95: =VLOOKUP(C95,'check dali wipday'!A:C,3,0) -> 8983943810;A | W95: =SUMIF('dali wip-fg'!A:A,C95,'dali wip-fg'!F:F) -> 194 | X95: =SUMIF('dali wip-fg'!A:A,V95,'dali wip-fg'!F:F) -> 1478 | Y95: =SUM(W95:X95) -> 1672 | Z95: =IF(Y95="","",IF(Y95<>Y94,Y95-F95,Z94-F95) ) -> 1567
A96: 0000100056 | B96: ISUZU MOTORS CO., (THAILAND) LTD. | C96: 8983943812 | D96: 8983943812 DUCT ASM;A/CL OTLT | E96: 30 | F96: 30 | G96: 46246 | H96: 114 | I96: 0 | J96: F-RP | K96: 46227 | L96: 0002243254 | S96: =VLOOKUP(C96,'check dali wipday'!A:A,1,0) -> 8983943812 | V96: =VLOOKUP(C96,'check dali wipday'!A:C,3,0) -> 8983943810;A | W96: =SUMIF('dali wip-fg'!A:A,C96,'dali wip-fg'!F:F) -> 194 | X96: =SUMIF('dali wip-fg'!A:A,V96,'dali wip-fg'!F:F) -> 1478 | Y96: =SUM(W96:X96) -> 1672 | Z96: =IF(Y96="","",IF(Y96<>Y95,Y96-F96,Z95-F96) ) -> 1537
A97: 0000100056 | B97: ISUZU MOTORS CO., (THAILAND) LTD. | C97: 8983943812 | D97: 8983943812 DUCT ASM;A/CL OTLT | E97: 45 | F97: 45 | G97: 46246 | H97: 114 | I97: 0 | J97: F-RP | K97: 46227 | L97: 0002243255 | S97: =VLOOKUP(C97,'check dali wipday'!A:A,1,0) -> 8983943812 | V97: =VLOOKUP(C97,'check dali wipday'!A:C,3,0) -> 8983943810;A | W97: =SUMIF('dali wip-fg'!A:A,C97,'dali wip-fg'!F:F) -> 194 | X97: =SUMIF('dali wip-fg'!A:A,V97,'dali wip-fg'!F:F) -> 1478 | Y97: =SUM(W97:X97) -> 1672 | Z97: =IF(Y97="","",IF(Y97<>Y96,Y97-F97,Z96-F97) ) -> 1492
A98: 0000100056 | B98: ISUZU MOTORS CO., (THAILAND) LTD. | C98: 8983943812 | D98: 8983943812 DUCT ASM;A/CL OTLT | E98: 45 | F98: 45 | G98: 46247 | H98: 114 | I98: 0 | J98: F-RP | K98: 46227 | L98: 0002243256 | S98: =VLOOKUP(C98,'check dali wipday'!A:A,1,0) -> 8983943812 | V98: =VLOOKUP(C98,'check dali wipday'!A:C,3,0) -> 8983943810;A | W98: =SUMIF('dali wip-fg'!A:A,C98,'dali wip-fg'!F:F) -> 194 | X98: =SUMIF('dali wip-fg'!A:A,V98,'dali wip-fg'!F:F) -> 1478 | Y98: =SUM(W98:X98) -> 1672 | Z98: =IF(Y98="","",IF(Y98<>Y97,Y98-F98,Z97-F98) ) -> 1447
A99: 0000100056 | B99: ISUZU MOTORS CO., (THAILAND) LTD. | C99: 8983943812 | D99: 8983943812 DUCT ASM;A/CL OTLT | E99: 45 | F99: 45 | G99: 46247 | H99: 114 | I99: 0 | J99: F-RP | K99: 46227 | L99: 0002243257 | S99: =VLOOKUP(C99,'check dali wipday'!A:A,1,0) -> 8983943812 | V99: =VLOOKUP(C99,'check dali wipday'!A:C,3,0) -> 8983943810;A | W99: =SUMIF('dali wip-fg'!A:A,C99,'dali wip-fg'!F:F) -> 194 | X99: =SUMIF('dali wip-fg'!A:A,V99,'dali wip-fg'!F:F) -> 1478 | Y99: =SUM(W99:X99) -> 1672 | Z99: =IF(Y99="","",IF(Y99<>Y98,Y99-F99,Z98-F99) ) -> 1402
A100: 0000100056 | B100: ISUZU MOTORS CO., (THAILAND) LTD. | C100: 8983943812 | D100: 8983943812 DUCT ASM;A/CL OTLT | E100: 45 | F100: 45 | G100: 46248 | H100: 114 | I100: 0 | J100: F-RP | K100: 46227 | L100: 0002243258 | S100: =VLOOKUP(C100,'check dali wipday'!A:A,1,0) -> 8983943812 | V100: =VLOOKUP(C100,'check dali wipday'!A:C,3,0) -> 8983943810;A | W100: =SUMIF('dali wip-fg'!A:A,C100,'dali wip-fg'!F:F) -> 194 | X100: =SUMIF('dali wip-fg'!A:A,V100,'dali wip-fg'!F:F) -> 1478 | Y100: =SUM(W100:X100) -> 1672 | Z100: =IF(Y100="","",IF(Y100<>Y99,Y100-F100,Z99-F100) ) -> 1357
A101: 0000100056 | B101: ISUZU MOTORS CO., (THAILAND) LTD. | C101: 8983943812 | D101: 8983943812 DUCT ASM;A/CL OTLT | E101: 30 | F101: 30 | G101: 46248 | H101: 114 | I101: 0 | J101: F-RP | K101: 46227 | L101: 0002243259 | S101: =VLOOKUP(C101,'check dali wipday'!A:A,1,0) -> 8983943812 | V101: =VLOOKUP(C101,'check dali wipday'!A:C,3,0) -> 8983943810;A | W101: =SUMIF('dali wip-fg'!A:A,C101,'dali wip-fg'!F:F) -> 194 | X101: =SUMIF('dali wip-fg'!A:A,V101,'dali wip-fg'!F:F) -> 1478 | Y101: =SUM(W101:X101) -> 1672 | Z101: =IF(Y101="","",IF(Y101<>Y100,Y101-F101,Z100-F101) ) -> 1327
A102: 0000100056 | B102: ISUZU MOTORS CO., (THAILAND) LTD. | C102: 8983943812 | D102: 8983943812 DUCT ASM;A/CL OTLT | E102: 75 | F102: 75 | G102: 46249 | H102: 114 | I102: 0 | J102: F-RP | K102: 46227 | L102: 0002243260 | S102: =VLOOKUP(C102,'check dali wipday'!A:A,1,0) -> 8983943812 | V102: =VLOOKUP(C102,'check dali wipday'!A:C,3,0) -> 8983943810;A | W102: =SUMIF('dali wip-fg'!A:A,C102,'dali wip-fg'!F:F) -> 194 | X102: =SUMIF('dali wip-fg'!A:A,V102,'dali wip-fg'!F:F) -> 1478 | Y102: =SUM(W102:X102) -> 1672 | Z102: =IF(Y102="","",IF(Y102<>Y101,Y102-F102,Z101-F102) ) -> 1252
A103: 0000100056 | B103: ISUZU MOTORS CO., (THAILAND) LTD. | C103: 8983943812 | D103: 8983943812 DUCT ASM;A/CL OTLT | E103: 30 | F103: 30 | G103: 46249 | H103: 114 | I103: 0 | J103: F-RP | K103: 46227 | L103: 0002243261 | S103: =VLOOKUP(C103,'check dali wipday'!A:A,1,0) -> 8983943812 | V103: =VLOOKUP(C103,'check dali wipday'!A:C,3,0) -> 8983943810;A | W103: =SUMIF('dali wip-fg'!A:A,C103,'dali wip-fg'!F:F) -> 194 | X103: =SUMIF('dali wip-fg'!A:A,V103,'dali wip-fg'!F:F) -> 1478 | Y103: =SUM(W103:X103) -> 1672 | Z103: =IF(Y103="","",IF(Y103<>Y102,Y103-F103,Z102-F103) ) -> 1222
